[2025-02-12T20:35:02.787+0000] {local_task_job_runner.py:120} INFO - ::group::Pre task execution logs
[2025-02-12T20:35:02.805+0000] {taskinstance.py:2076} INFO - Dependencies all met for dep_context=non-requeueable deps ti=<TaskInstance: call_omdb_api.teste scheduled__2025-02-12T20:33:00+00:00 [queued]>
[2025-02-12T20:35:02.811+0000] {taskinstance.py:2076} INFO - Dependencies all met for dep_context=requeueable deps ti=<TaskInstance: call_omdb_api.teste scheduled__2025-02-12T20:33:00+00:00 [queued]>
[2025-02-12T20:35:02.811+0000] {taskinstance.py:2306} INFO - Starting attempt 2 of 2
[2025-02-12T20:35:02.822+0000] {taskinstance.py:2330} INFO - Executing <Task(BashOperator): teste> on 2025-02-12 20:33:00+00:00
[2025-02-12T20:35:02.827+0000] {warnings.py:110} WARNING - /home/***/.local/lib/python3.12/site-packages/***/task/task_runner/standard_task_runner.py:61: DeprecationWarning: This process (pid=413) is multi-threaded, use of fork() may lead to deadlocks in the child.
  pid = os.fork()

[2025-02-12T20:35:02.828+0000] {standard_task_runner.py:63} INFO - Started process 414 to run task
[2025-02-12T20:35:02.828+0000] {standard_task_runner.py:90} INFO - Running: ['***', 'tasks', 'run', 'call_omdb_api', 'teste', 'scheduled__2025-02-12T20:33:00+00:00', '--job-id', '136', '--raw', '--subdir', 'DAGS_FOLDER/call_api.py', '--cfg-path', '/tmp/tmppqf9teeb']
[2025-02-12T20:35:02.829+0000] {standard_task_runner.py:91} INFO - Job 136: Subtask teste
[2025-02-12T20:35:02.861+0000] {task_command.py:426} INFO - Running <TaskInstance: call_omdb_api.teste scheduled__2025-02-12T20:33:00+00:00 [running]> on host a7cb053280af
[2025-02-12T20:35:02.924+0000] {taskinstance.py:2648} INFO - Exporting env vars: AIRFLOW_CTX_DAG_OWNER='Celso Cazetto' AIRFLOW_CTX_DAG_ID='call_omdb_api' AIRFLOW_CTX_TASK_ID='teste' AIRFLOW_CTX_EXECUTION_DATE='2025-02-12T20:33:00+00:00' AIRFLOW_CTX_TRY_NUMBER='2' AIRFLOW_CTX_DAG_RUN_ID='scheduled__2025-02-12T20:33:00+00:00'
[2025-02-12T20:35:02.925+0000] {taskinstance.py:430} INFO - ::endgroup::
[2025-02-12T20:35:02.934+0000] {subprocess.py:63} INFO - Tmp dir root location: /tmp
[2025-02-12T20:35:02.935+0000] {subprocess.py:75} INFO - Running command: ['/usr/bin/bash', '-c', 'python /opt/***/pipeline/main.py']
[2025-02-12T20:35:02.942+0000] {subprocess.py:86} INFO - Output:
[2025-02-12T20:35:03.859+0000] {subprocess.py:93} INFO - Traceback (most recent call last):
[2025-02-12T20:35:03.860+0000] {subprocess.py:93} INFO -   File "/opt/***/pipeline/main.py", line 20, in <module>
[2025-02-12T20:35:03.861+0000] {subprocess.py:93} INFO -     with open(file_path, 'r') as file:
[2025-02-12T20:35:03.861+0000] {subprocess.py:93} INFO -          ^^^^^^^^^^^^^^^^^^^^
[2025-02-12T20:35:03.862+0000] {subprocess.py:93} INFO - FileNotFoundError: [Errno 2] No such file or directory: '/tmp/***tmp7rzhjp95/config.json'
[2025-02-12T20:35:03.934+0000] {subprocess.py:97} INFO - Command exited with return code 1
[2025-02-12T20:35:03.935+0000] {taskinstance.py:441} INFO - ::group::Post task execution logs
[2025-02-12T20:35:03.944+0000] {taskinstance.py:2905} ERROR - Task failed with exception
Traceback (most recent call last):
  File "/home/airflow/.local/lib/python3.12/site-packages/airflow/models/taskinstance.py", line 465, in _execute_task
    result = _execute_callable(context=context, **execute_callable_kwargs)
             ^^^^^^^^^^^^^^^^^^^^^^^^^^^^^^^^^^^^^^^^^^^^^^^^^^^^^^^^^^^^^
  File "/home/airflow/.local/lib/python3.12/site-packages/airflow/models/taskinstance.py", line 432, in _execute_callable
    return execute_callable(context=context, **execute_callable_kwargs)
           ^^^^^^^^^^^^^^^^^^^^^^^^^^^^^^^^^^^^^^^^^^^^^^^^^^^^^^^^^^^^
  File "/home/airflow/.local/lib/python3.12/site-packages/airflow/models/baseoperator.py", line 400, in wrapper
    return func(self, *args, **kwargs)
           ^^^^^^^^^^^^^^^^^^^^^^^^^^^
  File "/home/airflow/.local/lib/python3.12/site-packages/airflow/operators/bash.py", line 243, in execute
    raise AirflowException(
airflow.exceptions.AirflowException: Bash command failed. The command returned a non-zero exit code 1.
[2025-02-12T20:35:03.947+0000] {taskinstance.py:1206} INFO - Marking task as FAILED. dag_id=call_omdb_api, task_id=teste, run_id=scheduled__2025-02-12T20:33:00+00:00, execution_date=20250212T203300, start_date=20250212T203502, end_date=20250212T203503
[2025-02-12T20:35:03.958+0000] {standard_task_runner.py:110} ERROR - Failed to execute job 136 for task teste (Bash command failed. The command returned a non-zero exit code 1.; 414)
[2025-02-12T20:35:03.974+0000] {local_task_job_runner.py:240} INFO - Task exited with return code 1
[2025-02-12T20:35:03.987+0000] {taskinstance.py:3498} INFO - 0 downstream tasks scheduled from follow-on schedule check
[2025-02-12T20:35:03.989+0000] {local_task_job_runner.py:222} INFO - ::endgroup::
