[2025-02-12T20:49:01.235+0000] {local_task_job_runner.py:120} INFO - ::group::Pre task execution logs
[2025-02-12T20:49:01.252+0000] {taskinstance.py:2076} INFO - Dependencies all met for dep_context=non-requeueable deps ti=<TaskInstance: call_omdb_api.teste scheduled__2025-02-12T20:48:00+00:00 [queued]>
[2025-02-12T20:49:01.258+0000] {taskinstance.py:2076} INFO - Dependencies all met for dep_context=requeueable deps ti=<TaskInstance: call_omdb_api.teste scheduled__2025-02-12T20:48:00+00:00 [queued]>
[2025-02-12T20:49:01.258+0000] {taskinstance.py:2306} INFO - Starting attempt 1 of 2
[2025-02-12T20:49:01.270+0000] {taskinstance.py:2330} INFO - Executing <Task(BashOperator): teste> on 2025-02-12 20:48:00+00:00
[2025-02-12T20:49:01.274+0000] {warnings.py:110} WARNING - /home/***/.local/lib/python3.12/site-packages/***/task/task_runner/standard_task_runner.py:61: DeprecationWarning: This process (pid=807) is multi-threaded, use of fork() may lead to deadlocks in the child.
  pid = os.fork()

[2025-02-12T20:49:01.275+0000] {standard_task_runner.py:63} INFO - Started process 808 to run task
[2025-02-12T20:49:01.276+0000] {standard_task_runner.py:90} INFO - Running: ['***', 'tasks', 'run', 'call_omdb_api', 'teste', 'scheduled__2025-02-12T20:48:00+00:00', '--job-id', '150', '--raw', '--subdir', 'DAGS_FOLDER/call_api.py', '--cfg-path', '/tmp/tmp9ox1qds6']
[2025-02-12T20:49:01.276+0000] {standard_task_runner.py:91} INFO - Job 150: Subtask teste
[2025-02-12T20:49:01.311+0000] {task_command.py:426} INFO - Running <TaskInstance: call_omdb_api.teste scheduled__2025-02-12T20:48:00+00:00 [running]> on host a7cb053280af
[2025-02-12T20:49:01.386+0000] {taskinstance.py:2648} INFO - Exporting env vars: AIRFLOW_CTX_DAG_OWNER='Celso Cazetto' AIRFLOW_CTX_DAG_ID='call_omdb_api' AIRFLOW_CTX_TASK_ID='teste' AIRFLOW_CTX_EXECUTION_DATE='2025-02-12T20:48:00+00:00' AIRFLOW_CTX_TRY_NUMBER='1' AIRFLOW_CTX_DAG_RUN_ID='scheduled__2025-02-12T20:48:00+00:00'
[2025-02-12T20:49:01.387+0000] {taskinstance.py:430} INFO - ::endgroup::
[2025-02-12T20:49:01.396+0000] {subprocess.py:63} INFO - Tmp dir root location: /tmp
[2025-02-12T20:49:01.397+0000] {subprocess.py:75} INFO - Running command: ['/usr/bin/bash', '-c', 'python /opt/***/pipeline/main.py']
[2025-02-12T20:49:01.405+0000] {subprocess.py:86} INFO - Output:
[2025-02-12T20:49:02.376+0000] {subprocess.py:93} INFO - 2025-02-12 20:49:02,376 - INFO - ESTOU RODANDO ESSA PORRA
[2025-02-12T20:49:02.377+0000] {subprocess.py:93} INFO - 2025-02-12 20:49:02,377 - INFO - Carregando o arquivo de configuração
[2025-02-12T20:49:02.378+0000] {subprocess.py:93} INFO - 2025-02-12 20:49:02,377 - INFO - Buscando os dados de filme do ID:tt0499549
[2025-02-12T20:49:02.488+0000] {subprocess.py:93} INFO - 2025-02-12 20:49:02,488 - INFO - Dados da API carregados com sucesso
[2025-02-12T20:49:02.488+0000] {subprocess.py:93} INFO - 2025-02-12 20:49:02,488 - INFO - Iniciando transformação dos dados.
[2025-02-12T20:49:02.496+0000] {subprocess.py:93} INFO - 2025-02-12 20:49:02,496 - INFO - Estabelecendo conexão com o banco de dados:
[2025-02-12T20:49:02.507+0000] {subprocess.py:93} INFO - 2025-02-12 20:49:02,507 - ERROR - Não foi possivel estabelecer a conexão com o banco de dados: (psycopg2.OperationalError) connection to server at "localhost" (::1), port 5432 failed: Connection refused
[2025-02-12T20:49:02.508+0000] {subprocess.py:93} INFO - 	Is the server running on that host and accepting TCP/IP connections?
[2025-02-12T20:49:02.508+0000] {subprocess.py:93} INFO - connection to server at "localhost" (127.0.0.1), port 5432 failed: Connection refused
[2025-02-12T20:49:02.508+0000] {subprocess.py:93} INFO - 	Is the server running on that host and accepting TCP/IP connections?
[2025-02-12T20:49:02.509+0000] {subprocess.py:93} INFO - 
[2025-02-12T20:49:02.509+0000] {subprocess.py:93} INFO - (Background on this error at: https://sqlalche.me/e/14/e3q8)
[2025-02-12T20:49:02.510+0000] {subprocess.py:93} INFO - Traceback (most recent call last):
[2025-02-12T20:49:02.510+0000] {subprocess.py:93} INFO -   File "/home/***/.local/lib/python3.12/site-packages/sqlalchemy/engine/base.py", line 3371, in _wrap_pool_connect
[2025-02-12T20:49:02.511+0000] {subprocess.py:93} INFO -     return fn()
[2025-02-12T20:49:02.511+0000] {subprocess.py:93} INFO -            ^^^^
[2025-02-12T20:49:02.511+0000] {subprocess.py:93} INFO -   File "/home/***/.local/lib/python3.12/site-packages/sqlalchemy/pool/base.py", line 327, in connect
[2025-02-12T20:49:02.512+0000] {subprocess.py:93} INFO -     return _ConnectionFairy._checkout(self)
[2025-02-12T20:49:02.512+0000] {subprocess.py:93} INFO -            ^^^^^^^^^^^^^^^^^^^^^^^^^^^^^^^^
[2025-02-12T20:49:02.512+0000] {subprocess.py:93} INFO -   File "/home/***/.local/lib/python3.12/site-packages/sqlalchemy/pool/base.py", line 894, in _checkout
[2025-02-12T20:49:02.513+0000] {subprocess.py:93} INFO -     fairy = _ConnectionRecord.checkout(pool)
[2025-02-12T20:49:02.513+0000] {subprocess.py:93} INFO -             ^^^^^^^^^^^^^^^^^^^^^^^^^^^^^^^^
[2025-02-12T20:49:02.513+0000] {subprocess.py:93} INFO -   File "/home/***/.local/lib/python3.12/site-packages/sqlalchemy/pool/base.py", line 493, in checkout
[2025-02-12T20:49:02.514+0000] {subprocess.py:93} INFO -     rec = pool._do_get()
[2025-02-12T20:49:02.514+0000] {subprocess.py:93} INFO -           ^^^^^^^^^^^^^^
[2025-02-12T20:49:02.514+0000] {subprocess.py:93} INFO -   File "/home/***/.local/lib/python3.12/site-packages/sqlalchemy/pool/impl.py", line 145, in _do_get
[2025-02-12T20:49:02.514+0000] {subprocess.py:93} INFO -     with util.safe_reraise():
[2025-02-12T20:49:02.515+0000] {subprocess.py:93} INFO -   File "/home/***/.local/lib/python3.12/site-packages/sqlalchemy/util/langhelpers.py", line 70, in __exit__
[2025-02-12T20:49:02.515+0000] {subprocess.py:93} INFO -     compat.raise_(
[2025-02-12T20:49:02.516+0000] {subprocess.py:93} INFO -   File "/home/***/.local/lib/python3.12/site-packages/sqlalchemy/util/compat.py", line 211, in raise_
[2025-02-12T20:49:02.516+0000] {subprocess.py:93} INFO -     raise exception
[2025-02-12T20:49:02.516+0000] {subprocess.py:93} INFO -   File "/home/***/.local/lib/python3.12/site-packages/sqlalchemy/pool/impl.py", line 143, in _do_get
[2025-02-12T20:49:02.517+0000] {subprocess.py:93} INFO -     return self._create_connection()
[2025-02-12T20:49:02.517+0000] {subprocess.py:93} INFO -            ^^^^^^^^^^^^^^^^^^^^^^^^^
[2025-02-12T20:49:02.517+0000] {subprocess.py:93} INFO -   File "/home/***/.local/lib/python3.12/site-packages/sqlalchemy/pool/base.py", line 273, in _create_connection
[2025-02-12T20:49:02.517+0000] {subprocess.py:93} INFO -     return _ConnectionRecord(self)
[2025-02-12T20:49:02.518+0000] {subprocess.py:93} INFO -            ^^^^^^^^^^^^^^^^^^^^^^^
[2025-02-12T20:49:02.518+0000] {subprocess.py:93} INFO -   File "/home/***/.local/lib/python3.12/site-packages/sqlalchemy/pool/base.py", line 388, in __init__
[2025-02-12T20:49:02.518+0000] {subprocess.py:93} INFO -     self.__connect()
[2025-02-12T20:49:02.518+0000] {subprocess.py:93} INFO -   File "/home/***/.local/lib/python3.12/site-packages/sqlalchemy/pool/base.py", line 690, in __connect
[2025-02-12T20:49:02.519+0000] {subprocess.py:93} INFO -     with util.safe_reraise():
[2025-02-12T20:49:02.519+0000] {subprocess.py:93} INFO -   File "/home/***/.local/lib/python3.12/site-packages/sqlalchemy/util/langhelpers.py", line 70, in __exit__
[2025-02-12T20:49:02.519+0000] {subprocess.py:93} INFO -     compat.raise_(
[2025-02-12T20:49:02.519+0000] {subprocess.py:93} INFO -   File "/home/***/.local/lib/python3.12/site-packages/sqlalchemy/util/compat.py", line 211, in raise_
[2025-02-12T20:49:02.520+0000] {subprocess.py:93} INFO -     raise exception
[2025-02-12T20:49:02.520+0000] {subprocess.py:93} INFO -   File "/home/***/.local/lib/python3.12/site-packages/sqlalchemy/pool/base.py", line 686, in __connect
[2025-02-12T20:49:02.520+0000] {subprocess.py:93} INFO -     self.dbapi_connection = connection = pool._invoke_creator(self)
[2025-02-12T20:49:02.520+0000] {subprocess.py:93} INFO -                                          ^^^^^^^^^^^^^^^^^^^^^^^^^^
[2025-02-12T20:49:02.521+0000] {subprocess.py:93} INFO -   File "/home/***/.local/lib/python3.12/site-packages/sqlalchemy/engine/create.py", line 574, in connect
[2025-02-12T20:49:02.521+0000] {subprocess.py:93} INFO -     return dialect.connect(*cargs, **cparams)
[2025-02-12T20:49:02.521+0000] {subprocess.py:93} INFO -            ^^^^^^^^^^^^^^^^^^^^^^^^^^^^^^^^^^
[2025-02-12T20:49:02.521+0000] {subprocess.py:93} INFO -   File "/home/***/.local/lib/python3.12/site-packages/sqlalchemy/engine/default.py", line 598, in connect
[2025-02-12T20:49:02.522+0000] {subprocess.py:93} INFO -     return self.dbapi.connect(*cargs, **cparams)
[2025-02-12T20:49:02.522+0000] {subprocess.py:93} INFO -            ^^^^^^^^^^^^^^^^^^^^^^^^^^^^^^^^^^^^^
[2025-02-12T20:49:02.522+0000] {subprocess.py:93} INFO -   File "/home/***/.local/lib/python3.12/site-packages/psycopg2/__init__.py", line 122, in connect
[2025-02-12T20:49:02.522+0000] {subprocess.py:93} INFO -     conn = _connect(dsn, connection_factory=connection_factory, **kwasync)
[2025-02-12T20:49:02.523+0000] {subprocess.py:93} INFO -            ^^^^^^^^^^^^^^^^^^^^^^^^^^^^^^^^^^^^^^^^^^^^^^^^^^^^^^^^^^^^^^^
[2025-02-12T20:49:02.523+0000] {subprocess.py:93} INFO - psycopg2.OperationalError: connection to server at "localhost" (::1), port 5432 failed: Connection refused
[2025-02-12T20:49:02.523+0000] {subprocess.py:93} INFO - 	Is the server running on that host and accepting TCP/IP connections?
[2025-02-12T20:49:02.524+0000] {subprocess.py:93} INFO - connection to server at "localhost" (127.0.0.1), port 5432 failed: Connection refused
[2025-02-12T20:49:02.524+0000] {subprocess.py:93} INFO - 	Is the server running on that host and accepting TCP/IP connections?
[2025-02-12T20:49:02.524+0000] {subprocess.py:93} INFO - 
[2025-02-12T20:49:02.525+0000] {subprocess.py:93} INFO - 
[2025-02-12T20:49:02.525+0000] {subprocess.py:93} INFO - The above exception was the direct cause of the following exception:
[2025-02-12T20:49:02.525+0000] {subprocess.py:93} INFO - 
[2025-02-12T20:49:02.525+0000] {subprocess.py:93} INFO - Traceback (most recent call last):
[2025-02-12T20:49:02.526+0000] {subprocess.py:93} INFO -   File "/opt/***/pipeline/main.py", line 88, in <module>
[2025-02-12T20:49:02.526+0000] {subprocess.py:93} INFO -     conn.insere_filmes(filme_df, 'filmes', genero_df, 'genero', 'filme_genero', 'omdb')
[2025-02-12T20:49:02.526+0000] {subprocess.py:93} INFO -   File "/opt/***/pipeline/connection.py", line 67, in insere_filmes
[2025-02-12T20:49:02.527+0000] {subprocess.py:93} INFO -     filmes_df.to_sql(filmes_table, self.engine, schema=schema, if_exists="append", index=False, \
[2025-02-12T20:49:02.527+0000] {subprocess.py:93} INFO -   File "/home/***/.local/lib/python3.12/site-packages/pandas/util/_decorators.py", line 333, in wrapper
[2025-02-12T20:49:02.527+0000] {subprocess.py:93} INFO -     return func(*args, **kwargs)
[2025-02-12T20:49:02.527+0000] {subprocess.py:93} INFO -            ^^^^^^^^^^^^^^^^^^^^^
[2025-02-12T20:49:02.528+0000] {subprocess.py:93} INFO -   File "/home/***/.local/lib/python3.12/site-packages/pandas/core/generic.py", line 3008, in to_sql
[2025-02-12T20:49:02.528+0000] {subprocess.py:93} INFO -     return sql.to_sql(
[2025-02-12T20:49:02.528+0000] {subprocess.py:93} INFO -            ^^^^^^^^^^^
[2025-02-12T20:49:02.528+0000] {subprocess.py:93} INFO -   File "/home/***/.local/lib/python3.12/site-packages/pandas/io/sql.py", line 787, in to_sql
[2025-02-12T20:49:02.528+0000] {subprocess.py:93} INFO -     with pandasSQL_builder(con, schema=schema, need_transaction=True) as pandas_sql:
[2025-02-12T20:49:02.529+0000] {subprocess.py:93} INFO -          ^^^^^^^^^^^^^^^^^^^^^^^^^^^^^^^^^^^^^^^^^^^^^^^^^^^^^^^^^^^^
[2025-02-12T20:49:02.529+0000] {subprocess.py:93} INFO -   File "/home/***/.local/lib/python3.12/site-packages/pandas/io/sql.py", line 851, in pandasSQL_builder
[2025-02-12T20:49:02.529+0000] {subprocess.py:93} INFO -     return SQLDatabase(con, schema, need_transaction)
[2025-02-12T20:49:02.529+0000] {subprocess.py:93} INFO -            ^^^^^^^^^^^^^^^^^^^^^^^^^^^^^^^^^^^^^^^^^^
[2025-02-12T20:49:02.530+0000] {subprocess.py:93} INFO -   File "/home/***/.local/lib/python3.12/site-packages/pandas/io/sql.py", line 1576, in __init__
[2025-02-12T20:49:02.530+0000] {subprocess.py:93} INFO -     con = self.exit_stack.enter_context(con.connect())
[2025-02-12T20:49:02.530+0000] {subprocess.py:93} INFO -                                         ^^^^^^^^^^^^^
[2025-02-12T20:49:02.530+0000] {subprocess.py:93} INFO -   File "/home/***/.local/lib/python3.12/site-packages/sqlalchemy/engine/base.py", line 3325, in connect
[2025-02-12T20:49:02.531+0000] {subprocess.py:93} INFO -     return self._connection_cls(self, close_with_result=close_with_result)
[2025-02-12T20:49:02.531+0000] {subprocess.py:93} INFO -            ^^^^^^^^^^^^^^^^^^^^^^^^^^^^^^^^^^^^^^^^^^^^^^^^^^^^^^^^^^^^^^^
[2025-02-12T20:49:02.531+0000] {subprocess.py:93} INFO -   File "/home/***/.local/lib/python3.12/site-packages/sqlalchemy/engine/base.py", line 96, in __init__
[2025-02-12T20:49:02.531+0000] {subprocess.py:93} INFO -     else engine.raw_connection()
[2025-02-12T20:49:02.532+0000] {subprocess.py:93} INFO -          ^^^^^^^^^^^^^^^^^^^^^^^
[2025-02-12T20:49:02.532+0000] {subprocess.py:93} INFO -   File "/home/***/.local/lib/python3.12/site-packages/sqlalchemy/engine/base.py", line 3404, in raw_connection
[2025-02-12T20:49:02.532+0000] {subprocess.py:93} INFO -     return self._wrap_pool_connect(self.pool.connect, _connection)
[2025-02-12T20:49:02.533+0000] {subprocess.py:93} INFO -            ^^^^^^^^^^^^^^^^^^^^^^^^^^^^^^^^^^^^^^^^^^^^^^^^^^^^^^^
[2025-02-12T20:49:02.533+0000] {subprocess.py:93} INFO -   File "/home/***/.local/lib/python3.12/site-packages/sqlalchemy/engine/base.py", line 3374, in _wrap_pool_connect
[2025-02-12T20:49:02.533+0000] {subprocess.py:93} INFO -     Connection._handle_dbapi_exception_noconnection(
[2025-02-12T20:49:02.533+0000] {subprocess.py:93} INFO -   File "/home/***/.local/lib/python3.12/site-packages/sqlalchemy/engine/base.py", line 2208, in _handle_dbapi_exception_noconnection
[2025-02-12T20:49:02.534+0000] {subprocess.py:93} INFO -     util.raise_(
[2025-02-12T20:49:02.534+0000] {subprocess.py:93} INFO -   File "/home/***/.local/lib/python3.12/site-packages/sqlalchemy/util/compat.py", line 211, in raise_
[2025-02-12T20:49:02.534+0000] {subprocess.py:93} INFO -     raise exception
[2025-02-12T20:49:02.534+0000] {subprocess.py:93} INFO -   File "/home/***/.local/lib/python3.12/site-packages/sqlalchemy/engine/base.py", line 3371, in _wrap_pool_connect
[2025-02-12T20:49:02.535+0000] {subprocess.py:93} INFO -     return fn()
[2025-02-12T20:49:02.535+0000] {subprocess.py:93} INFO -            ^^^^
[2025-02-12T20:49:02.535+0000] {subprocess.py:93} INFO -   File "/home/***/.local/lib/python3.12/site-packages/sqlalchemy/pool/base.py", line 327, in connect
[2025-02-12T20:49:02.535+0000] {subprocess.py:93} INFO -     return _ConnectionFairy._checkout(self)
[2025-02-12T20:49:02.535+0000] {subprocess.py:93} INFO -            ^^^^^^^^^^^^^^^^^^^^^^^^^^^^^^^^
[2025-02-12T20:49:02.536+0000] {subprocess.py:93} INFO -   File "/home/***/.local/lib/python3.12/site-packages/sqlalchemy/pool/base.py", line 894, in _checkout
[2025-02-12T20:49:02.536+0000] {subprocess.py:93} INFO -     fairy = _ConnectionRecord.checkout(pool)
[2025-02-12T20:49:02.536+0000] {subprocess.py:93} INFO -             ^^^^^^^^^^^^^^^^^^^^^^^^^^^^^^^^
[2025-02-12T20:49:02.536+0000] {subprocess.py:93} INFO -   File "/home/***/.local/lib/python3.12/site-packages/sqlalchemy/pool/base.py", line 493, in checkout
[2025-02-12T20:49:02.537+0000] {subprocess.py:93} INFO -     rec = pool._do_get()
[2025-02-12T20:49:02.537+0000] {subprocess.py:93} INFO -           ^^^^^^^^^^^^^^
[2025-02-12T20:49:02.537+0000] {subprocess.py:93} INFO -   File "/home/***/.local/lib/python3.12/site-packages/sqlalchemy/pool/impl.py", line 145, in _do_get
[2025-02-12T20:49:02.537+0000] {subprocess.py:93} INFO -     with util.safe_reraise():
[2025-02-12T20:49:02.538+0000] {subprocess.py:93} INFO -   File "/home/***/.local/lib/python3.12/site-packages/sqlalchemy/util/langhelpers.py", line 70, in __exit__
[2025-02-12T20:49:02.538+0000] {subprocess.py:93} INFO -     compat.raise_(
[2025-02-12T20:49:02.538+0000] {subprocess.py:93} INFO -   File "/home/***/.local/lib/python3.12/site-packages/sqlalchemy/util/compat.py", line 211, in raise_
[2025-02-12T20:49:02.538+0000] {subprocess.py:93} INFO -     raise exception
[2025-02-12T20:49:02.539+0000] {subprocess.py:93} INFO -   File "/home/***/.local/lib/python3.12/site-packages/sqlalchemy/pool/impl.py", line 143, in _do_get
[2025-02-12T20:49:02.539+0000] {subprocess.py:93} INFO -     return self._create_connection()
[2025-02-12T20:49:02.539+0000] {subprocess.py:93} INFO -            ^^^^^^^^^^^^^^^^^^^^^^^^^
[2025-02-12T20:49:02.539+0000] {subprocess.py:93} INFO -   File "/home/***/.local/lib/python3.12/site-packages/sqlalchemy/pool/base.py", line 273, in _create_connection
[2025-02-12T20:49:02.540+0000] {subprocess.py:93} INFO -     return _ConnectionRecord(self)
[2025-02-12T20:49:02.540+0000] {subprocess.py:93} INFO -            ^^^^^^^^^^^^^^^^^^^^^^^
[2025-02-12T20:49:02.540+0000] {subprocess.py:93} INFO -   File "/home/***/.local/lib/python3.12/site-packages/sqlalchemy/pool/base.py", line 388, in __init__
[2025-02-12T20:49:02.540+0000] {subprocess.py:93} INFO -     self.__connect()
[2025-02-12T20:49:02.541+0000] {subprocess.py:93} INFO -   File "/home/***/.local/lib/python3.12/site-packages/sqlalchemy/pool/base.py", line 690, in __connect
[2025-02-12T20:49:02.541+0000] {subprocess.py:93} INFO -     with util.safe_reraise():
[2025-02-12T20:49:02.541+0000] {subprocess.py:93} INFO -   File "/home/***/.local/lib/python3.12/site-packages/sqlalchemy/util/langhelpers.py", line 70, in __exit__
[2025-02-12T20:49:02.542+0000] {subprocess.py:93} INFO -     compat.raise_(
[2025-02-12T20:49:02.542+0000] {subprocess.py:93} INFO -   File "/home/***/.local/lib/python3.12/site-packages/sqlalchemy/util/compat.py", line 211, in raise_
[2025-02-12T20:49:02.542+0000] {subprocess.py:93} INFO -     raise exception
[2025-02-12T20:49:02.542+0000] {subprocess.py:93} INFO -   File "/home/***/.local/lib/python3.12/site-packages/sqlalchemy/pool/base.py", line 686, in __connect
[2025-02-12T20:49:02.543+0000] {subprocess.py:93} INFO -     self.dbapi_connection = connection = pool._invoke_creator(self)
[2025-02-12T20:49:02.543+0000] {subprocess.py:93} INFO -                                          ^^^^^^^^^^^^^^^^^^^^^^^^^^
[2025-02-12T20:49:02.543+0000] {subprocess.py:93} INFO -   File "/home/***/.local/lib/python3.12/site-packages/sqlalchemy/engine/create.py", line 574, in connect
[2025-02-12T20:49:02.543+0000] {subprocess.py:93} INFO -     return dialect.connect(*cargs, **cparams)
[2025-02-12T20:49:02.543+0000] {subprocess.py:93} INFO -            ^^^^^^^^^^^^^^^^^^^^^^^^^^^^^^^^^^
[2025-02-12T20:49:02.544+0000] {subprocess.py:93} INFO -   File "/home/***/.local/lib/python3.12/site-packages/sqlalchemy/engine/default.py", line 598, in connect
[2025-02-12T20:49:02.544+0000] {subprocess.py:93} INFO -     return self.dbapi.connect(*cargs, **cparams)
[2025-02-12T20:49:02.544+0000] {subprocess.py:93} INFO -            ^^^^^^^^^^^^^^^^^^^^^^^^^^^^^^^^^^^^^
[2025-02-12T20:49:02.544+0000] {subprocess.py:93} INFO -   File "/home/***/.local/lib/python3.12/site-packages/psycopg2/__init__.py", line 122, in connect
[2025-02-12T20:49:02.545+0000] {subprocess.py:93} INFO -     conn = _connect(dsn, connection_factory=connection_factory, **kwasync)
[2025-02-12T20:49:02.545+0000] {subprocess.py:93} INFO -            ^^^^^^^^^^^^^^^^^^^^^^^^^^^^^^^^^^^^^^^^^^^^^^^^^^^^^^^^^^^^^^^
[2025-02-12T20:49:02.545+0000] {subprocess.py:93} INFO - sqlalchemy.exc.OperationalError: (psycopg2.OperationalError) connection to server at "localhost" (::1), port 5432 failed: Connection refused
[2025-02-12T20:49:02.545+0000] {subprocess.py:93} INFO - 	Is the server running on that host and accepting TCP/IP connections?
[2025-02-12T20:49:02.545+0000] {subprocess.py:93} INFO - connection to server at "localhost" (127.0.0.1), port 5432 failed: Connection refused
[2025-02-12T20:49:02.546+0000] {subprocess.py:93} INFO - 	Is the server running on that host and accepting TCP/IP connections?
[2025-02-12T20:49:02.546+0000] {subprocess.py:93} INFO - 
[2025-02-12T20:49:02.546+0000] {subprocess.py:93} INFO - (Background on this error at: https://sqlalche.me/e/14/e3q8)
[2025-02-12T20:49:02.607+0000] {subprocess.py:97} INFO - Command exited with return code 1
[2025-02-12T20:49:02.608+0000] {taskinstance.py:441} INFO - ::group::Post task execution logs
[2025-02-12T20:49:02.617+0000] {taskinstance.py:2905} ERROR - Task failed with exception
Traceback (most recent call last):
  File "/home/airflow/.local/lib/python3.12/site-packages/airflow/models/taskinstance.py", line 465, in _execute_task
    result = _execute_callable(context=context, **execute_callable_kwargs)
             ^^^^^^^^^^^^^^^^^^^^^^^^^^^^^^^^^^^^^^^^^^^^^^^^^^^^^^^^^^^^^
  File "/home/airflow/.local/lib/python3.12/site-packages/airflow/models/taskinstance.py", line 432, in _execute_callable
    return execute_callable(context=context, **execute_callable_kwargs)
           ^^^^^^^^^^^^^^^^^^^^^^^^^^^^^^^^^^^^^^^^^^^^^^^^^^^^^^^^^^^^
  File "/home/airflow/.local/lib/python3.12/site-packages/airflow/models/baseoperator.py", line 400, in wrapper
    return func(self, *args, **kwargs)
           ^^^^^^^^^^^^^^^^^^^^^^^^^^^
  File "/home/airflow/.local/lib/python3.12/site-packages/airflow/operators/bash.py", line 243, in execute
    raise AirflowException(
airflow.exceptions.AirflowException: Bash command failed. The command returned a non-zero exit code 1.
[2025-02-12T20:49:02.621+0000] {taskinstance.py:1206} INFO - Marking task as UP_FOR_RETRY. dag_id=call_omdb_api, task_id=teste, run_id=scheduled__2025-02-12T20:48:00+00:00, execution_date=20250212T204800, start_date=20250212T204901, end_date=20250212T204902
[2025-02-12T20:49:02.658+0000] {standard_task_runner.py:110} ERROR - Failed to execute job 150 for task teste (Bash command failed. The command returned a non-zero exit code 1.; 808)
[2025-02-12T20:49:02.695+0000] {local_task_job_runner.py:240} INFO - Task exited with return code 1
[2025-02-12T20:49:02.710+0000] {taskinstance.py:3498} INFO - 0 downstream tasks scheduled from follow-on schedule check
[2025-02-12T20:49:02.734+0000] {local_task_job_runner.py:222} INFO - ::endgroup::
