[2025-02-12T20:11:49.091+0000] {local_task_job_runner.py:120} INFO - ::group::Pre task execution logs
[2025-02-12T20:11:49.108+0000] {taskinstance.py:2076} INFO - Dependencies all met for dep_context=non-requeueable deps ti=<TaskInstance: call_omdb_api.teste manual__2025-02-12T20:10:47.452865+00:00 [queued]>
[2025-02-12T20:11:49.114+0000] {taskinstance.py:2076} INFO - Dependencies all met for dep_context=requeueable deps ti=<TaskInstance: call_omdb_api.teste manual__2025-02-12T20:10:47.452865+00:00 [queued]>
[2025-02-12T20:11:49.115+0000] {taskinstance.py:2306} INFO - Starting attempt 2 of 2
[2025-02-12T20:11:49.125+0000] {taskinstance.py:2330} INFO - Executing <Task(BashOperator): teste> on 2025-02-12 20:10:47.452865+00:00
[2025-02-12T20:11:49.130+0000] {warnings.py:110} WARNING - /home/***/.local/lib/python3.12/site-packages/***/task/task_runner/standard_task_runner.py:61: DeprecationWarning: This process (pid=932) is multi-threaded, use of fork() may lead to deadlocks in the child.
  pid = os.fork()

[2025-02-12T20:11:49.131+0000] {standard_task_runner.py:63} INFO - Started process 933 to run task
[2025-02-12T20:11:49.132+0000] {standard_task_runner.py:90} INFO - Running: ['***', 'tasks', 'run', 'call_omdb_api', 'teste', 'manual__2025-02-12T20:10:47.452865+00:00', '--job-id', '82', '--raw', '--subdir', 'DAGS_FOLDER/call_api.py', '--cfg-path', '/tmp/tmpgflisd1r']
[2025-02-12T20:11:49.132+0000] {standard_task_runner.py:91} INFO - Job 82: Subtask teste
[2025-02-12T20:11:49.165+0000] {task_command.py:426} INFO - Running <TaskInstance: call_omdb_api.teste manual__2025-02-12T20:10:47.452865+00:00 [running]> on host f82bf6a6274c
[2025-02-12T20:11:49.232+0000] {taskinstance.py:2648} INFO - Exporting env vars: AIRFLOW_CTX_DAG_OWNER='Celso Cazetto' AIRFLOW_CTX_DAG_ID='call_omdb_api' AIRFLOW_CTX_TASK_ID='teste' AIRFLOW_CTX_EXECUTION_DATE='2025-02-12T20:10:47.452865+00:00' AIRFLOW_CTX_TRY_NUMBER='2' AIRFLOW_CTX_DAG_RUN_ID='manual__2025-02-12T20:10:47.452865+00:00'
[2025-02-12T20:11:49.233+0000] {taskinstance.py:430} INFO - ::endgroup::
[2025-02-12T20:11:49.243+0000] {subprocess.py:63} INFO - Tmp dir root location: /tmp
[2025-02-12T20:11:49.245+0000] {subprocess.py:75} INFO - Running command: ['/usr/bin/bash', '-c', 'python ~/***/pipeline/.main.py']
[2025-02-12T20:11:49.252+0000] {subprocess.py:86} INFO - Output:
[2025-02-12T20:11:49.298+0000] {subprocess.py:93} INFO - python: can't open file '/home/***/***/pipeline/.main.py': [Errno 2] No such file or directory
[2025-02-12T20:11:49.301+0000] {subprocess.py:97} INFO - Command exited with return code 2
[2025-02-12T20:11:49.302+0000] {taskinstance.py:441} INFO - ::group::Post task execution logs
[2025-02-12T20:11:49.310+0000] {taskinstance.py:2905} ERROR - Task failed with exception
Traceback (most recent call last):
  File "/home/airflow/.local/lib/python3.12/site-packages/airflow/models/taskinstance.py", line 465, in _execute_task
    result = _execute_callable(context=context, **execute_callable_kwargs)
             ^^^^^^^^^^^^^^^^^^^^^^^^^^^^^^^^^^^^^^^^^^^^^^^^^^^^^^^^^^^^^
  File "/home/airflow/.local/lib/python3.12/site-packages/airflow/models/taskinstance.py", line 432, in _execute_callable
    return execute_callable(context=context, **execute_callable_kwargs)
           ^^^^^^^^^^^^^^^^^^^^^^^^^^^^^^^^^^^^^^^^^^^^^^^^^^^^^^^^^^^^
  File "/home/airflow/.local/lib/python3.12/site-packages/airflow/models/baseoperator.py", line 400, in wrapper
    return func(self, *args, **kwargs)
           ^^^^^^^^^^^^^^^^^^^^^^^^^^^
  File "/home/airflow/.local/lib/python3.12/site-packages/airflow/operators/bash.py", line 243, in execute
    raise AirflowException(
airflow.exceptions.AirflowException: Bash command failed. The command returned a non-zero exit code 2.
[2025-02-12T20:11:49.314+0000] {taskinstance.py:1206} INFO - Marking task as FAILED. dag_id=call_omdb_api, task_id=teste, run_id=manual__2025-02-12T20:10:47.452865+00:00, execution_date=20250212T201047, start_date=20250212T201149, end_date=20250212T201149
[2025-02-12T20:11:49.324+0000] {standard_task_runner.py:110} ERROR - Failed to execute job 82 for task teste (Bash command failed. The command returned a non-zero exit code 2.; 933)
[2025-02-12T20:11:49.345+0000] {local_task_job_runner.py:240} INFO - Task exited with return code 1
[2025-02-12T20:11:49.359+0000] {taskinstance.py:3498} INFO - 0 downstream tasks scheduled from follow-on schedule check
[2025-02-12T20:11:49.361+0000] {local_task_job_runner.py:222} INFO - ::endgroup::
