[2025-02-12T19:55:25.193+0000] {local_task_job_runner.py:120} INFO - ::group::Pre task execution logs
[2025-02-12T19:55:25.211+0000] {taskinstance.py:2076} INFO - Dependencies all met for dep_context=non-requeueable deps ti=<TaskInstance: call_omdb_api.teste manual__2025-02-12T19:55:23.808405+00:00 [queued]>
[2025-02-12T19:55:25.217+0000] {taskinstance.py:2076} INFO - Dependencies all met for dep_context=requeueable deps ti=<TaskInstance: call_omdb_api.teste manual__2025-02-12T19:55:23.808405+00:00 [queued]>
[2025-02-12T19:55:25.217+0000] {taskinstance.py:2306} INFO - Starting attempt 1 of 2
[2025-02-12T19:55:25.230+0000] {taskinstance.py:2330} INFO - Executing <Task(PythonOperator): teste> on 2025-02-12 19:55:23.808405+00:00
[2025-02-12T19:55:25.235+0000] {warnings.py:110} WARNING - /home/***/.local/lib/python3.12/site-packages/***/task/task_runner/standard_task_runner.py:61: DeprecationWarning: This process (pid=622) is multi-threaded, use of fork() may lead to deadlocks in the child.
  pid = os.fork()

[2025-02-12T19:55:25.236+0000] {standard_task_runner.py:63} INFO - Started process 623 to run task
[2025-02-12T19:55:25.236+0000] {standard_task_runner.py:90} INFO - Running: ['***', 'tasks', 'run', 'call_omdb_api', 'teste', 'manual__2025-02-12T19:55:23.808405+00:00', '--job-id', '59', '--raw', '--subdir', 'DAGS_FOLDER/call_api.py', '--cfg-path', '/tmp/tmpnxzk93ls']
[2025-02-12T19:55:25.237+0000] {standard_task_runner.py:91} INFO - Job 59: Subtask teste
[2025-02-12T19:55:25.272+0000] {task_command.py:426} INFO - Running <TaskInstance: call_omdb_api.teste manual__2025-02-12T19:55:23.808405+00:00 [running]> on host f82bf6a6274c
[2025-02-12T19:55:25.341+0000] {taskinstance.py:2648} INFO - Exporting env vars: AIRFLOW_CTX_DAG_OWNER='Celso Cazetto' AIRFLOW_CTX_DAG_ID='call_omdb_api' AIRFLOW_CTX_TASK_ID='teste' AIRFLOW_CTX_EXECUTION_DATE='2025-02-12T19:55:23.808405+00:00' AIRFLOW_CTX_TRY_NUMBER='1' AIRFLOW_CTX_DAG_RUN_ID='manual__2025-02-12T19:55:23.808405+00:00'
[2025-02-12T19:55:25.342+0000] {taskinstance.py:430} INFO - ::endgroup::
[2025-02-12T19:55:25.352+0000] {logging_mixin.py:188} INFO - CURRENT PATH /opt/***
[2025-02-12T19:55:25.353+0000] {taskinstance.py:441} INFO - ::group::Post task execution logs
[2025-02-12T19:55:25.354+0000] {taskinstance.py:2905} ERROR - Task failed with exception
Traceback (most recent call last):
  File "/home/airflow/.local/lib/python3.12/site-packages/airflow/models/taskinstance.py", line 465, in _execute_task
    result = _execute_callable(context=context, **execute_callable_kwargs)
             ^^^^^^^^^^^^^^^^^^^^^^^^^^^^^^^^^^^^^^^^^^^^^^^^^^^^^^^^^^^^^
  File "/home/airflow/.local/lib/python3.12/site-packages/airflow/models/taskinstance.py", line 432, in _execute_callable
    return execute_callable(context=context, **execute_callable_kwargs)
           ^^^^^^^^^^^^^^^^^^^^^^^^^^^^^^^^^^^^^^^^^^^^^^^^^^^^^^^^^^^^
  File "/home/airflow/.local/lib/python3.12/site-packages/airflow/models/baseoperator.py", line 400, in wrapper
    return func(self, *args, **kwargs)
           ^^^^^^^^^^^^^^^^^^^^^^^^^^^
  File "/home/airflow/.local/lib/python3.12/site-packages/airflow/operators/python.py", line 235, in execute
    return_value = self.execute_callable()
                   ^^^^^^^^^^^^^^^^^^^^^^^
  File "/home/airflow/.local/lib/python3.12/site-packages/airflow/operators/python.py", line 252, in execute_callable
    return self.python_callable(*self.op_args, **self.op_kwargs)
           ^^^^^^^^^^^^^^^^^^^^^^^^^^^^^^^^^^^^^^^^^^^^^^^^^^^^^
  File "/opt/airflow/dags/call_api.py", line 23, in call_api
    path_test = os.path.exists(os.getcwd(), 'pipeline')
                ^^^^^^^^^^^^^^^^^^^^^^^^^^^^^^^^^^^^^^^
TypeError: exists() takes 1 positional argument but 2 were given
[2025-02-12T19:55:25.370+0000] {taskinstance.py:1206} INFO - Marking task as UP_FOR_RETRY. dag_id=call_omdb_api, task_id=teste, run_id=manual__2025-02-12T19:55:23.808405+00:00, execution_date=20250212T195523, start_date=20250212T195525, end_date=20250212T195525
[2025-02-12T19:55:25.382+0000] {standard_task_runner.py:110} ERROR - Failed to execute job 59 for task teste (exists() takes 1 positional argument but 2 were given; 623)
[2025-02-12T19:55:25.410+0000] {local_task_job_runner.py:240} INFO - Task exited with return code 1
[2025-02-12T19:55:25.426+0000] {taskinstance.py:3498} INFO - 0 downstream tasks scheduled from follow-on schedule check
[2025-02-12T19:55:25.428+0000] {local_task_job_runner.py:222} INFO - ::endgroup::
