[2025-02-12T20:59:03.431+0000] {local_task_job_runner.py:120} INFO - ::group::Pre task execution logs
[2025-02-12T20:59:03.448+0000] {taskinstance.py:2076} INFO - Dependencies all met for dep_context=non-requeueable deps ti=<TaskInstance: call_omdb_api.teste scheduled__2025-02-12T20:57:00+00:00 [queued]>
[2025-02-12T20:59:03.454+0000] {taskinstance.py:2076} INFO - Dependencies all met for dep_context=requeueable deps ti=<TaskInstance: call_omdb_api.teste scheduled__2025-02-12T20:57:00+00:00 [queued]>
[2025-02-12T20:59:03.454+0000] {taskinstance.py:2306} INFO - Starting attempt 2 of 2
[2025-02-12T20:59:03.466+0000] {taskinstance.py:2330} INFO - Executing <Task(BashOperator): teste> on 2025-02-12 20:57:00+00:00
[2025-02-12T20:59:03.471+0000] {warnings.py:110} WARNING - /home/***/.local/lib/python3.12/site-packages/***/task/task_runner/standard_task_runner.py:61: DeprecationWarning: This process (pid=1330) is multi-threaded, use of fork() may lead to deadlocks in the child.
  pid = os.fork()

[2025-02-12T20:59:03.472+0000] {standard_task_runner.py:63} INFO - Started process 1331 to run task
[2025-02-12T20:59:03.473+0000] {standard_task_runner.py:90} INFO - Running: ['***', 'tasks', 'run', 'call_omdb_api', 'teste', 'scheduled__2025-02-12T20:57:00+00:00', '--job-id', '176', '--raw', '--subdir', 'DAGS_FOLDER/call_api.py', '--cfg-path', '/tmp/tmpzk86c39g']
[2025-02-12T20:59:03.473+0000] {standard_task_runner.py:91} INFO - Job 176: Subtask teste
[2025-02-12T20:59:03.510+0000] {task_command.py:426} INFO - Running <TaskInstance: call_omdb_api.teste scheduled__2025-02-12T20:57:00+00:00 [running]> on host a7cb053280af
[2025-02-12T20:59:03.588+0000] {taskinstance.py:2648} INFO - Exporting env vars: AIRFLOW_CTX_DAG_OWNER='Celso Cazetto' AIRFLOW_CTX_DAG_ID='call_omdb_api' AIRFLOW_CTX_TASK_ID='teste' AIRFLOW_CTX_EXECUTION_DATE='2025-02-12T20:57:00+00:00' AIRFLOW_CTX_TRY_NUMBER='2' AIRFLOW_CTX_DAG_RUN_ID='scheduled__2025-02-12T20:57:00+00:00'
[2025-02-12T20:59:03.589+0000] {taskinstance.py:430} INFO - ::endgroup::
[2025-02-12T20:59:03.603+0000] {subprocess.py:63} INFO - Tmp dir root location: /tmp
[2025-02-12T20:59:03.604+0000] {subprocess.py:75} INFO - Running command: ['/usr/bin/bash', '-c', 'python /opt/***/pipeline/main.py']
[2025-02-12T20:59:03.615+0000] {subprocess.py:86} INFO - Output:
[2025-02-12T20:59:04.608+0000] {subprocess.py:93} INFO - 2025-02-12 20:59:04,608 - INFO - ESTOU RODANDO ESSA PORRA
[2025-02-12T20:59:04.609+0000] {subprocess.py:93} INFO - 2025-02-12 20:59:04,609 - INFO - Carregando o arquivo de configuração
[2025-02-12T20:59:04.610+0000] {subprocess.py:93} INFO - 2025-02-12 20:59:04,610 - INFO - Buscando os dados de filme do ID:tt0499549
[2025-02-12T20:59:04.810+0000] {subprocess.py:93} INFO - 2025-02-12 20:59:04,810 - INFO - Dados da API carregados com sucesso
[2025-02-12T20:59:04.810+0000] {subprocess.py:93} INFO - 2025-02-12 20:59:04,810 - INFO - Iniciando transformação dos dados.
[2025-02-12T20:59:04.817+0000] {subprocess.py:93} INFO - 2025-02-12 20:59:04,817 - INFO - Estabelecendo conexão com o banco de dados:
[2025-02-12T20:59:04.860+0000] {subprocess.py:93} INFO - 2025-02-12 20:59:04,859 - INFO - Conexão estabelecida com sucesso.
[2025-02-12T20:59:04.884+0000] {subprocess.py:93} INFO - 2025-02-12 20:59:04,883 - INFO - Iniciando o inserção na tabela: omdb.filmes
[2025-02-12T20:59:04.887+0000] {subprocess.py:93} INFO - 2025-02-12 20:59:04,887 - INFO - 0 Inseridos na tabela omdb.filmes
[2025-02-12T20:59:04.891+0000] {subprocess.py:93} INFO - 2025-02-12 20:59:04,891 - INFO - Iniciando o inserção na tabela: omdb.genero
[2025-02-12T20:59:04.895+0000] {subprocess.py:93} INFO - 2025-02-12 20:59:04,894 - INFO - 0 Inseridos na tabela omdb.genero
[2025-02-12T20:59:04.904+0000] {subprocess.py:93} INFO - 2025-02-12 20:59:04,904 - INFO - Iniciando o inserção na tabela: omdb.filme_genero
[2025-02-12T20:59:04.907+0000] {subprocess.py:93} INFO - 2025-02-12 20:59:04,907 - INFO - 0 Inseridos na tabela omdb.filme_genero
[2025-02-12T20:59:04.908+0000] {subprocess.py:93} INFO - Traceback (most recent call last):
[2025-02-12T20:59:04.909+0000] {subprocess.py:93} INFO -   File "/opt/***/pipeline/main.py", line 88, in <module>
[2025-02-12T20:59:04.910+0000] {subprocess.py:93} INFO -     conn.insere_filmes(filme_df, 'filmes', genero_df, 'genero', 'filme_genero', 'omdb')
[2025-02-12T20:59:04.911+0000] {subprocess.py:93} INFO -   File "/opt/***/pipeline/connection.py", line 79, in insere_filmes
[2025-02-12T20:59:04.912+0000] {subprocess.py:93} INFO -     self.close()
[2025-02-12T20:59:04.912+0000] {subprocess.py:93} INFO -   File "/opt/***/pipeline/connection.py", line 36, in close
[2025-02-12T20:59:04.914+0000] {subprocess.py:93} INFO -     self.conn.commit()
[2025-02-12T20:59:04.914+0000] {subprocess.py:93} INFO -     ^^^^^^^^^^^^^^^^
[2025-02-12T20:59:04.914+0000] {subprocess.py:93} INFO - AttributeError: 'Connection' object has no attribute 'commit'
[2025-02-12T20:59:05.014+0000] {subprocess.py:97} INFO - Command exited with return code 1
[2025-02-12T20:59:05.015+0000] {taskinstance.py:441} INFO - ::group::Post task execution logs
[2025-02-12T20:59:05.024+0000] {taskinstance.py:2905} ERROR - Task failed with exception
Traceback (most recent call last):
  File "/home/airflow/.local/lib/python3.12/site-packages/airflow/models/taskinstance.py", line 465, in _execute_task
    result = _execute_callable(context=context, **execute_callable_kwargs)
             ^^^^^^^^^^^^^^^^^^^^^^^^^^^^^^^^^^^^^^^^^^^^^^^^^^^^^^^^^^^^^
  File "/home/airflow/.local/lib/python3.12/site-packages/airflow/models/taskinstance.py", line 432, in _execute_callable
    return execute_callable(context=context, **execute_callable_kwargs)
           ^^^^^^^^^^^^^^^^^^^^^^^^^^^^^^^^^^^^^^^^^^^^^^^^^^^^^^^^^^^^
  File "/home/airflow/.local/lib/python3.12/site-packages/airflow/models/baseoperator.py", line 400, in wrapper
    return func(self, *args, **kwargs)
           ^^^^^^^^^^^^^^^^^^^^^^^^^^^
  File "/home/airflow/.local/lib/python3.12/site-packages/airflow/operators/bash.py", line 243, in execute
    raise AirflowException(
airflow.exceptions.AirflowException: Bash command failed. The command returned a non-zero exit code 1.
[2025-02-12T20:59:05.028+0000] {taskinstance.py:1206} INFO - Marking task as FAILED. dag_id=call_omdb_api, task_id=teste, run_id=scheduled__2025-02-12T20:57:00+00:00, execution_date=20250212T205700, start_date=20250212T205903, end_date=20250212T205905
[2025-02-12T20:59:05.039+0000] {standard_task_runner.py:110} ERROR - Failed to execute job 176 for task teste (Bash command failed. The command returned a non-zero exit code 1.; 1331)
[2025-02-12T20:59:05.050+0000] {local_task_job_runner.py:240} INFO - Task exited with return code 1
[2025-02-12T20:59:05.063+0000] {taskinstance.py:3498} INFO - 0 downstream tasks scheduled from follow-on schedule check
[2025-02-12T20:59:05.065+0000] {local_task_job_runner.py:222} INFO - ::endgroup::
