[2025-02-12T23:10:07.970+0000] {local_task_job_runner.py:123} INFO - ::group::Pre task execution logs
[2025-02-12T23:10:07.983+0000] {taskinstance.py:2614} INFO - Dependencies all met for dep_context=non-requeueable deps ti=<TaskInstance: call_omdb_api.teste scheduled__2025-02-12T23:08:00+00:00 [queued]>
[2025-02-12T23:10:07.988+0000] {taskinstance.py:2614} INFO - Dependencies all met for dep_context=requeueable deps ti=<TaskInstance: call_omdb_api.teste scheduled__2025-02-12T23:08:00+00:00 [queued]>
[2025-02-12T23:10:07.989+0000] {taskinstance.py:2867} INFO - Starting attempt 2 of 2
[2025-02-12T23:10:07.998+0000] {taskinstance.py:2890} INFO - Executing <Task(BashOperator): teste> on 2025-02-12 23:08:00+00:00
[2025-02-12T23:10:08.003+0000] {warnings.py:112} WARNING - /home/***/.local/lib/python3.12/site-packages/***/task/task_runner/standard_task_runner.py:70: DeprecationWarning: This process (pid=153) is multi-threaded, use of fork() may lead to deadlocks in the child.
  pid = os.fork()

[2025-02-12T23:10:08.004+0000] {standard_task_runner.py:72} INFO - Started process 155 to run task
[2025-02-12T23:10:08.004+0000] {standard_task_runner.py:104} INFO - Running: ['***', 'tasks', 'run', 'call_omdb_api', 'teste', 'scheduled__2025-02-12T23:08:00+00:00', '--job-id', '7', '--raw', '--subdir', 'DAGS_FOLDER/call_api.py', '--cfg-path', '/tmp/tmp2x97nikq']
[2025-02-12T23:10:08.005+0000] {standard_task_runner.py:105} INFO - Job 7: Subtask teste
[2025-02-12T23:10:08.039+0000] {task_command.py:467} INFO - Running <TaskInstance: call_omdb_api.teste scheduled__2025-02-12T23:08:00+00:00 [running]> on host e1e426aee594
[2025-02-12T23:10:08.133+0000] {taskinstance.py:3134} INFO - Exporting env vars: AIRFLOW_CTX_DAG_OWNER='Celso Cazetto' AIRFLOW_CTX_DAG_ID='call_omdb_api' AIRFLOW_CTX_TASK_ID='teste' AIRFLOW_CTX_EXECUTION_DATE='2025-02-12T23:08:00+00:00' AIRFLOW_CTX_TRY_NUMBER='2' AIRFLOW_CTX_DAG_RUN_ID='scheduled__2025-02-12T23:08:00+00:00'
[2025-02-12T23:10:08.133+0000] {taskinstance.py:732} INFO - ::endgroup::
[2025-02-12T23:10:08.143+0000] {subprocess.py:78} INFO - Tmp dir root location: /tmp
[2025-02-12T23:10:08.144+0000] {subprocess.py:88} INFO - Running command: ['/usr/bin/bash', '-c', 'source /home/***/venv/omdb_env/bin/activate && python /opt/***/pipeline/main.py']
[2025-02-12T23:10:08.156+0000] {subprocess.py:99} INFO - Output:
[2025-02-12T23:10:08.174+0000] {subprocess.py:106} INFO - Traceback (most recent call last):
[2025-02-12T23:10:08.174+0000] {subprocess.py:106} INFO -   File "/opt/***/pipeline/main.py", line 2, in <module>
[2025-02-12T23:10:08.175+0000] {subprocess.py:106} INFO -     import requests
[2025-02-12T23:10:08.176+0000] {subprocess.py:106} INFO - ModuleNotFoundError: No module named 'requests'
[2025-02-12T23:10:08.177+0000] {subprocess.py:110} INFO - Command exited with return code 1
[2025-02-12T23:10:08.187+0000] {taskinstance.py:3313} ERROR - Task failed with exception
Traceback (most recent call last):
  File "/home/airflow/.local/lib/python3.12/site-packages/airflow/models/taskinstance.py", line 768, in _execute_task
    result = _execute_callable(context=context, **execute_callable_kwargs)
             ^^^^^^^^^^^^^^^^^^^^^^^^^^^^^^^^^^^^^^^^^^^^^^^^^^^^^^^^^^^^^
  File "/home/airflow/.local/lib/python3.12/site-packages/airflow/models/taskinstance.py", line 734, in _execute_callable
    return ExecutionCallableRunner(
           ^^^^^^^^^^^^^^^^^^^^^^^^
  File "/home/airflow/.local/lib/python3.12/site-packages/airflow/utils/operator_helpers.py", line 252, in run
    return self.func(*args, **kwargs)
           ^^^^^^^^^^^^^^^^^^^^^^^^^^
  File "/home/airflow/.local/lib/python3.12/site-packages/airflow/models/baseoperator.py", line 424, in wrapper
    return func(self, *args, **kwargs)
           ^^^^^^^^^^^^^^^^^^^^^^^^^^^
  File "/home/airflow/.local/lib/python3.12/site-packages/airflow/operators/bash.py", line 276, in execute
    raise AirflowException(
airflow.exceptions.AirflowException: Bash command failed. The command returned a non-zero exit code 1.
[2025-02-12T23:10:08.191+0000] {taskinstance.py:1226} INFO - Marking task as FAILED. dag_id=call_omdb_api, task_id=teste, run_id=scheduled__2025-02-12T23:08:00+00:00, execution_date=20250212T230800, start_date=20250212T231007, end_date=20250212T231008
[2025-02-12T23:10:08.211+0000] {taskinstance.py:341} INFO - ::group::Post task execution logs
[2025-02-12T23:10:08.212+0000] {standard_task_runner.py:124} ERROR - Failed to execute job 7 for task teste (Bash command failed. The command returned a non-zero exit code 1.; 155)
Traceback (most recent call last):
  File "/home/airflow/.local/lib/python3.12/site-packages/airflow/task/task_runner/standard_task_runner.py", line 117, in _start_by_fork
    ret = args.func(args, dag=self.dag)
          ^^^^^^^^^^^^^^^^^^^^^^^^^^^^^
  File "/home/airflow/.local/lib/python3.12/site-packages/airflow/cli/cli_config.py", line 49, in command
    return func(*args, **kwargs)
           ^^^^^^^^^^^^^^^^^^^^^
  File "/home/airflow/.local/lib/python3.12/site-packages/airflow/utils/cli.py", line 116, in wrapper
    return f(*args, **kwargs)
           ^^^^^^^^^^^^^^^^^^
  File "/home/airflow/.local/lib/python3.12/site-packages/airflow/cli/commands/task_command.py", line 483, in task_run
    task_return_code = _run_task_by_selected_method(args, _dag, ti)
                       ^^^^^^^^^^^^^^^^^^^^^^^^^^^^^^^^^^^^^^^^^^^^
  File "/home/airflow/.local/lib/python3.12/site-packages/airflow/cli/commands/task_command.py", line 256, in _run_task_by_selected_method
    return _run_raw_task(args, ti)
           ^^^^^^^^^^^^^^^^^^^^^^^
  File "/home/airflow/.local/lib/python3.12/site-packages/airflow/cli/commands/task_command.py", line 341, in _run_raw_task
    return ti._run_raw_task(
           ^^^^^^^^^^^^^^^^^
  File "/home/airflow/.local/lib/python3.12/site-packages/airflow/utils/session.py", line 97, in wrapper
    return func(*args, session=session, **kwargs)
           ^^^^^^^^^^^^^^^^^^^^^^^^^^^^^^^^^^^^^^
  File "/home/airflow/.local/lib/python3.12/site-packages/airflow/models/taskinstance.py", line 3006, in _run_raw_task
    return _run_raw_task(
           ^^^^^^^^^^^^^^
  File "/home/airflow/.local/lib/python3.12/site-packages/airflow/models/taskinstance.py", line 274, in _run_raw_task
    TaskInstance._execute_task_with_callbacks(
  File "/home/airflow/.local/lib/python3.12/site-packages/airflow/models/taskinstance.py", line 3161, in _execute_task_with_callbacks
    result = self._execute_task(context, task_orig)
             ^^^^^^^^^^^^^^^^^^^^^^^^^^^^^^^^^^^^^^
  File "/home/airflow/.local/lib/python3.12/site-packages/airflow/models/taskinstance.py", line 3185, in _execute_task
    return _execute_task(self, context, task_orig)
           ^^^^^^^^^^^^^^^^^^^^^^^^^^^^^^^^^^^^^^^
  File "/home/airflow/.local/lib/python3.12/site-packages/airflow/models/taskinstance.py", line 768, in _execute_task
    result = _execute_callable(context=context, **execute_callable_kwargs)
             ^^^^^^^^^^^^^^^^^^^^^^^^^^^^^^^^^^^^^^^^^^^^^^^^^^^^^^^^^^^^^
  File "/home/airflow/.local/lib/python3.12/site-packages/airflow/models/taskinstance.py", line 734, in _execute_callable
    return ExecutionCallableRunner(
           ^^^^^^^^^^^^^^^^^^^^^^^^
  File "/home/airflow/.local/lib/python3.12/site-packages/airflow/utils/operator_helpers.py", line 252, in run
    return self.func(*args, **kwargs)
           ^^^^^^^^^^^^^^^^^^^^^^^^^^
  File "/home/airflow/.local/lib/python3.12/site-packages/airflow/models/baseoperator.py", line 424, in wrapper
    return func(self, *args, **kwargs)
           ^^^^^^^^^^^^^^^^^^^^^^^^^^^
  File "/home/airflow/.local/lib/python3.12/site-packages/airflow/operators/bash.py", line 276, in execute
    raise AirflowException(
airflow.exceptions.AirflowException: Bash command failed. The command returned a non-zero exit code 1.
[2025-02-12T23:10:08.259+0000] {local_task_job_runner.py:266} INFO - Task exited with return code 1
[2025-02-12T23:10:08.271+0000] {taskinstance.py:3901} INFO - 0 downstream tasks scheduled from follow-on schedule check
[2025-02-12T23:10:08.273+0000] {local_task_job_runner.py:245} INFO - ::endgroup::
