[2025-02-12T20:25:00.394+0000] {local_task_job_runner.py:120} INFO - ::group::Pre task execution logs
[2025-02-12T20:25:00.412+0000] {taskinstance.py:2076} INFO - Dependencies all met for dep_context=non-requeueable deps ti=<TaskInstance: call_omdb_api.teste scheduled__2025-02-12T20:24:00+00:00 [queued]>
[2025-02-12T20:25:00.418+0000] {taskinstance.py:2076} INFO - Dependencies all met for dep_context=requeueable deps ti=<TaskInstance: call_omdb_api.teste scheduled__2025-02-12T20:24:00+00:00 [queued]>
[2025-02-12T20:25:00.419+0000] {taskinstance.py:2306} INFO - Starting attempt 1 of 2
[2025-02-12T20:25:00.430+0000] {taskinstance.py:2330} INFO - Executing <Task(BashOperator): teste> on 2025-02-12 20:24:00+00:00
[2025-02-12T20:25:00.437+0000] {warnings.py:110} WARNING - /home/***/.local/lib/python3.12/site-packages/***/task/task_runner/standard_task_runner.py:61: DeprecationWarning: This process (pid=450) is multi-threaded, use of fork() may lead to deadlocks in the child.
  pid = os.fork()

[2025-02-12T20:25:00.438+0000] {standard_task_runner.py:90} INFO - Running: ['***', 'tasks', 'run', 'call_omdb_api', 'teste', 'scheduled__2025-02-12T20:24:00+00:00', '--job-id', '113', '--raw', '--subdir', 'DAGS_FOLDER/call_api.py', '--cfg-path', '/tmp/tmpun4lkdov']
[2025-02-12T20:25:00.439+0000] {standard_task_runner.py:63} INFO - Started process 451 to run task
[2025-02-12T20:25:00.439+0000] {standard_task_runner.py:91} INFO - Job 113: Subtask teste
[2025-02-12T20:25:00.478+0000] {task_command.py:426} INFO - Running <TaskInstance: call_omdb_api.teste scheduled__2025-02-12T20:24:00+00:00 [running]> on host 201af4902dc5
[2025-02-12T20:25:00.545+0000] {taskinstance.py:2648} INFO - Exporting env vars: AIRFLOW_CTX_DAG_OWNER='Celso Cazetto' AIRFLOW_CTX_DAG_ID='call_omdb_api' AIRFLOW_CTX_TASK_ID='teste' AIRFLOW_CTX_EXECUTION_DATE='2025-02-12T20:24:00+00:00' AIRFLOW_CTX_TRY_NUMBER='1' AIRFLOW_CTX_DAG_RUN_ID='scheduled__2025-02-12T20:24:00+00:00'
[2025-02-12T20:25:00.546+0000] {taskinstance.py:430} INFO - ::endgroup::
[2025-02-12T20:25:00.556+0000] {subprocess.py:63} INFO - Tmp dir root location: /tmp
[2025-02-12T20:25:00.557+0000] {subprocess.py:75} INFO - Running command: ['/usr/bin/bash', '-c', 'python /opt/***/pipeline/main.py']
[2025-02-12T20:25:00.565+0000] {subprocess.py:86} INFO - Output:
[2025-02-12T20:25:01.550+0000] {subprocess.py:93} INFO - Traceback (most recent call last):
[2025-02-12T20:25:01.551+0000] {subprocess.py:93} INFO -   File "/opt/***/pipeline/main.py", line 20, in <module>
[2025-02-12T20:25:01.552+0000] {subprocess.py:93} INFO -     with open(file_path2, 'r') as file:
[2025-02-12T20:25:01.553+0000] {subprocess.py:93} INFO -          ^^^^^^^^^^^^^^^^^^^^^
[2025-02-12T20:25:01.553+0000] {subprocess.py:93} INFO - FileNotFoundError: [Errno 2] No such file or directory: '/tmp/***tmpcnycfatm/pipeline/config.json'
[2025-02-12T20:25:01.683+0000] {subprocess.py:97} INFO - Command exited with return code 1
[2025-02-12T20:25:01.684+0000] {taskinstance.py:441} INFO - ::group::Post task execution logs
[2025-02-12T20:25:01.694+0000] {taskinstance.py:2905} ERROR - Task failed with exception
Traceback (most recent call last):
  File "/home/airflow/.local/lib/python3.12/site-packages/airflow/models/taskinstance.py", line 465, in _execute_task
    result = _execute_callable(context=context, **execute_callable_kwargs)
             ^^^^^^^^^^^^^^^^^^^^^^^^^^^^^^^^^^^^^^^^^^^^^^^^^^^^^^^^^^^^^
  File "/home/airflow/.local/lib/python3.12/site-packages/airflow/models/taskinstance.py", line 432, in _execute_callable
    return execute_callable(context=context, **execute_callable_kwargs)
           ^^^^^^^^^^^^^^^^^^^^^^^^^^^^^^^^^^^^^^^^^^^^^^^^^^^^^^^^^^^^
  File "/home/airflow/.local/lib/python3.12/site-packages/airflow/models/baseoperator.py", line 400, in wrapper
    return func(self, *args, **kwargs)
           ^^^^^^^^^^^^^^^^^^^^^^^^^^^
  File "/home/airflow/.local/lib/python3.12/site-packages/airflow/operators/bash.py", line 243, in execute
    raise AirflowException(
airflow.exceptions.AirflowException: Bash command failed. The command returned a non-zero exit code 1.
[2025-02-12T20:25:01.698+0000] {taskinstance.py:1206} INFO - Marking task as UP_FOR_RETRY. dag_id=call_omdb_api, task_id=teste, run_id=scheduled__2025-02-12T20:24:00+00:00, execution_date=20250212T202400, start_date=20250212T202500, end_date=20250212T202501
[2025-02-12T20:25:01.710+0000] {standard_task_runner.py:110} ERROR - Failed to execute job 113 for task teste (Bash command failed. The command returned a non-zero exit code 1.; 451)
[2025-02-12T20:25:01.736+0000] {local_task_job_runner.py:240} INFO - Task exited with return code 1
[2025-02-12T20:25:01.755+0000] {taskinstance.py:3498} INFO - 0 downstream tasks scheduled from follow-on schedule check
[2025-02-12T20:25:01.757+0000] {local_task_job_runner.py:222} INFO - ::endgroup::
