[2025-02-12T20:20:03.160+0000] {local_task_job_runner.py:120} INFO - ::group::Pre task execution logs
[2025-02-12T20:20:03.177+0000] {taskinstance.py:2076} INFO - Dependencies all met for dep_context=non-requeueable deps ti=<TaskInstance: call_omdb_api.teste scheduled__2025-02-12T20:18:00+00:00 [queued]>
[2025-02-12T20:20:03.182+0000] {taskinstance.py:2076} INFO - Dependencies all met for dep_context=requeueable deps ti=<TaskInstance: call_omdb_api.teste scheduled__2025-02-12T20:18:00+00:00 [queued]>
[2025-02-12T20:20:03.183+0000] {taskinstance.py:2306} INFO - Starting attempt 2 of 2
[2025-02-12T20:20:03.194+0000] {taskinstance.py:2330} INFO - Executing <Task(BashOperator): teste> on 2025-02-12 20:18:00+00:00
[2025-02-12T20:20:03.199+0000] {warnings.py:110} WARNING - /home/***/.local/lib/python3.12/site-packages/***/task/task_runner/standard_task_runner.py:61: DeprecationWarning: This process (pid=245) is multi-threaded, use of fork() may lead to deadlocks in the child.
  pid = os.fork()

[2025-02-12T20:20:03.200+0000] {standard_task_runner.py:63} INFO - Started process 246 to run task
[2025-02-12T20:20:03.200+0000] {standard_task_runner.py:90} INFO - Running: ['***', 'tasks', 'run', 'call_omdb_api', 'teste', 'scheduled__2025-02-12T20:18:00+00:00', '--job-id', '104', '--raw', '--subdir', 'DAGS_FOLDER/call_api.py', '--cfg-path', '/tmp/tmp_gyjqhmk']
[2025-02-12T20:20:03.201+0000] {standard_task_runner.py:91} INFO - Job 104: Subtask teste
[2025-02-12T20:20:03.233+0000] {task_command.py:426} INFO - Running <TaskInstance: call_omdb_api.teste scheduled__2025-02-12T20:18:00+00:00 [running]> on host 201af4902dc5
[2025-02-12T20:20:03.295+0000] {taskinstance.py:2648} INFO - Exporting env vars: AIRFLOW_CTX_DAG_OWNER='Celso Cazetto' AIRFLOW_CTX_DAG_ID='call_omdb_api' AIRFLOW_CTX_TASK_ID='teste' AIRFLOW_CTX_EXECUTION_DATE='2025-02-12T20:18:00+00:00' AIRFLOW_CTX_TRY_NUMBER='2' AIRFLOW_CTX_DAG_RUN_ID='scheduled__2025-02-12T20:18:00+00:00'
[2025-02-12T20:20:03.296+0000] {taskinstance.py:430} INFO - ::endgroup::
[2025-02-12T20:20:03.305+0000] {subprocess.py:63} INFO - Tmp dir root location: /tmp
[2025-02-12T20:20:03.306+0000] {subprocess.py:75} INFO - Running command: ['/usr/bin/bash', '-c', 'python /opt/***/pipeline/main.py']
[2025-02-12T20:20:03.314+0000] {subprocess.py:86} INFO - Output:
[2025-02-12T20:20:04.213+0000] {subprocess.py:93} INFO - Traceback (most recent call last):
[2025-02-12T20:20:04.213+0000] {subprocess.py:93} INFO -   File "/opt/***/pipeline/main.py", line 20, in <module>
[2025-02-12T20:20:04.214+0000] {subprocess.py:93} INFO -     with open(file_path2, 'r') as file:
[2025-02-12T20:20:04.215+0000] {subprocess.py:93} INFO -          ^^^^^^^^^^^^^^^^^^^^^
[2025-02-12T20:20:04.215+0000] {subprocess.py:93} INFO - FileNotFoundError: [Errno 2] No such file or directory: '/tmp/***tmpmqj0a7i3/pipeline/config.json'
[2025-02-12T20:20:04.284+0000] {subprocess.py:97} INFO - Command exited with return code 1
[2025-02-12T20:20:04.285+0000] {taskinstance.py:441} INFO - ::group::Post task execution logs
[2025-02-12T20:20:04.294+0000] {taskinstance.py:2905} ERROR - Task failed with exception
Traceback (most recent call last):
  File "/home/airflow/.local/lib/python3.12/site-packages/airflow/models/taskinstance.py", line 465, in _execute_task
    result = _execute_callable(context=context, **execute_callable_kwargs)
             ^^^^^^^^^^^^^^^^^^^^^^^^^^^^^^^^^^^^^^^^^^^^^^^^^^^^^^^^^^^^^
  File "/home/airflow/.local/lib/python3.12/site-packages/airflow/models/taskinstance.py", line 432, in _execute_callable
    return execute_callable(context=context, **execute_callable_kwargs)
           ^^^^^^^^^^^^^^^^^^^^^^^^^^^^^^^^^^^^^^^^^^^^^^^^^^^^^^^^^^^^
  File "/home/airflow/.local/lib/python3.12/site-packages/airflow/models/baseoperator.py", line 400, in wrapper
    return func(self, *args, **kwargs)
           ^^^^^^^^^^^^^^^^^^^^^^^^^^^
  File "/home/airflow/.local/lib/python3.12/site-packages/airflow/operators/bash.py", line 243, in execute
    raise AirflowException(
airflow.exceptions.AirflowException: Bash command failed. The command returned a non-zero exit code 1.
[2025-02-12T20:20:04.298+0000] {taskinstance.py:1206} INFO - Marking task as FAILED. dag_id=call_omdb_api, task_id=teste, run_id=scheduled__2025-02-12T20:18:00+00:00, execution_date=20250212T201800, start_date=20250212T202003, end_date=20250212T202004
[2025-02-12T20:20:04.309+0000] {standard_task_runner.py:110} ERROR - Failed to execute job 104 for task teste (Bash command failed. The command returned a non-zero exit code 1.; 246)
[2025-02-12T20:20:04.336+0000] {local_task_job_runner.py:240} INFO - Task exited with return code 1
[2025-02-12T20:20:04.349+0000] {taskinstance.py:3498} INFO - 0 downstream tasks scheduled from follow-on schedule check
[2025-02-12T20:20:04.351+0000] {local_task_job_runner.py:222} INFO - ::endgroup::
