[2025-02-12T20:52:00.594+0000] {local_task_job_runner.py:120} INFO - ::group::Pre task execution logs
[2025-02-12T20:52:00.611+0000] {taskinstance.py:2076} INFO - Dependencies all met for dep_context=non-requeueable deps ti=<TaskInstance: call_omdb_api.teste scheduled__2025-02-12T20:51:00+00:00 [queued]>
[2025-02-12T20:52:00.616+0000] {taskinstance.py:2076} INFO - Dependencies all met for dep_context=requeueable deps ti=<TaskInstance: call_omdb_api.teste scheduled__2025-02-12T20:51:00+00:00 [queued]>
[2025-02-12T20:52:00.617+0000] {taskinstance.py:2306} INFO - Starting attempt 1 of 2
[2025-02-12T20:52:00.629+0000] {taskinstance.py:2330} INFO - Executing <Task(BashOperator): teste> on 2025-02-12 20:51:00+00:00
[2025-02-12T20:52:00.633+0000] {warnings.py:110} WARNING - /home/***/.local/lib/python3.12/site-packages/***/task/task_runner/standard_task_runner.py:61: DeprecationWarning: This process (pid=954) is multi-threaded, use of fork() may lead to deadlocks in the child.
  pid = os.fork()

[2025-02-12T20:52:00.634+0000] {standard_task_runner.py:63} INFO - Started process 955 to run task
[2025-02-12T20:52:00.634+0000] {standard_task_runner.py:90} INFO - Running: ['***', 'tasks', 'run', 'call_omdb_api', 'teste', 'scheduled__2025-02-12T20:51:00+00:00', '--job-id', '157', '--raw', '--subdir', 'DAGS_FOLDER/call_api.py', '--cfg-path', '/tmp/tmp6nmr0x7z']
[2025-02-12T20:52:00.635+0000] {standard_task_runner.py:91} INFO - Job 157: Subtask teste
[2025-02-12T20:52:00.668+0000] {task_command.py:426} INFO - Running <TaskInstance: call_omdb_api.teste scheduled__2025-02-12T20:51:00+00:00 [running]> on host a7cb053280af
[2025-02-12T20:52:00.737+0000] {taskinstance.py:2648} INFO - Exporting env vars: AIRFLOW_CTX_DAG_OWNER='Celso Cazetto' AIRFLOW_CTX_DAG_ID='call_omdb_api' AIRFLOW_CTX_TASK_ID='teste' AIRFLOW_CTX_EXECUTION_DATE='2025-02-12T20:51:00+00:00' AIRFLOW_CTX_TRY_NUMBER='1' AIRFLOW_CTX_DAG_RUN_ID='scheduled__2025-02-12T20:51:00+00:00'
[2025-02-12T20:52:00.737+0000] {taskinstance.py:430} INFO - ::endgroup::
[2025-02-12T20:52:00.747+0000] {subprocess.py:63} INFO - Tmp dir root location: /tmp
[2025-02-12T20:52:00.747+0000] {subprocess.py:75} INFO - Running command: ['/usr/bin/bash', '-c', 'python /opt/***/pipeline/main.py']
[2025-02-12T20:52:00.754+0000] {subprocess.py:86} INFO - Output:
[2025-02-12T20:52:01.661+0000] {subprocess.py:93} INFO - 2025-02-12 20:52:01,661 - INFO - ESTOU RODANDO ESSA PORRA
[2025-02-12T20:52:01.662+0000] {subprocess.py:93} INFO - 2025-02-12 20:52:01,662 - INFO - Carregando o arquivo de configuração
[2025-02-12T20:52:01.663+0000] {subprocess.py:93} INFO - 2025-02-12 20:52:01,663 - INFO - Buscando os dados de filme do ID:tt0499549
[2025-02-12T20:52:01.770+0000] {subprocess.py:93} INFO - 2025-02-12 20:52:01,769 - INFO - Dados da API carregados com sucesso
[2025-02-12T20:52:01.770+0000] {subprocess.py:93} INFO - 2025-02-12 20:52:01,769 - INFO - Iniciando transformação dos dados.
[2025-02-12T20:52:01.777+0000] {subprocess.py:93} INFO - 2025-02-12 20:52:01,777 - INFO - Estabelecendo conexão com o banco de dados:
[2025-02-12T20:52:01.788+0000] {subprocess.py:93} INFO - 2025-02-12 20:52:01,788 - ERROR - Não foi possivel estabelecer a conexão com o banco de dados: (psycopg2.OperationalError) connection to server at "localhost" (::1), port 5432 failed: Connection refused
[2025-02-12T20:52:01.789+0000] {subprocess.py:93} INFO - 	Is the server running on that host and accepting TCP/IP connections?
[2025-02-12T20:52:01.789+0000] {subprocess.py:93} INFO - connection to server at "localhost" (127.0.0.1), port 5432 failed: Connection refused
[2025-02-12T20:52:01.789+0000] {subprocess.py:93} INFO - 	Is the server running on that host and accepting TCP/IP connections?
[2025-02-12T20:52:01.790+0000] {subprocess.py:93} INFO - 
[2025-02-12T20:52:01.790+0000] {subprocess.py:93} INFO - (Background on this error at: https://sqlalche.me/e/14/e3q8)
[2025-02-12T20:52:01.792+0000] {subprocess.py:93} INFO - Traceback (most recent call last):
[2025-02-12T20:52:01.792+0000] {subprocess.py:93} INFO -   File "/home/***/.local/lib/python3.12/site-packages/sqlalchemy/engine/base.py", line 3371, in _wrap_pool_connect
[2025-02-12T20:52:01.793+0000] {subprocess.py:93} INFO -     return fn()
[2025-02-12T20:52:01.793+0000] {subprocess.py:93} INFO -            ^^^^
[2025-02-12T20:52:01.793+0000] {subprocess.py:93} INFO -   File "/home/***/.local/lib/python3.12/site-packages/sqlalchemy/pool/base.py", line 327, in connect
[2025-02-12T20:52:01.794+0000] {subprocess.py:93} INFO -     return _ConnectionFairy._checkout(self)
[2025-02-12T20:52:01.794+0000] {subprocess.py:93} INFO -            ^^^^^^^^^^^^^^^^^^^^^^^^^^^^^^^^
[2025-02-12T20:52:01.794+0000] {subprocess.py:93} INFO -   File "/home/***/.local/lib/python3.12/site-packages/sqlalchemy/pool/base.py", line 894, in _checkout
[2025-02-12T20:52:01.795+0000] {subprocess.py:93} INFO -     fairy = _ConnectionRecord.checkout(pool)
[2025-02-12T20:52:01.795+0000] {subprocess.py:93} INFO -             ^^^^^^^^^^^^^^^^^^^^^^^^^^^^^^^^
[2025-02-12T20:52:01.795+0000] {subprocess.py:93} INFO -   File "/home/***/.local/lib/python3.12/site-packages/sqlalchemy/pool/base.py", line 493, in checkout
[2025-02-12T20:52:01.796+0000] {subprocess.py:93} INFO -     rec = pool._do_get()
[2025-02-12T20:52:01.796+0000] {subprocess.py:93} INFO -           ^^^^^^^^^^^^^^
[2025-02-12T20:52:01.796+0000] {subprocess.py:93} INFO -   File "/home/***/.local/lib/python3.12/site-packages/sqlalchemy/pool/impl.py", line 145, in _do_get
[2025-02-12T20:52:01.796+0000] {subprocess.py:93} INFO -     with util.safe_reraise():
[2025-02-12T20:52:01.797+0000] {subprocess.py:93} INFO -   File "/home/***/.local/lib/python3.12/site-packages/sqlalchemy/util/langhelpers.py", line 70, in __exit__
[2025-02-12T20:52:01.797+0000] {subprocess.py:93} INFO -     compat.raise_(
[2025-02-12T20:52:01.797+0000] {subprocess.py:93} INFO -   File "/home/***/.local/lib/python3.12/site-packages/sqlalchemy/util/compat.py", line 211, in raise_
[2025-02-12T20:52:01.798+0000] {subprocess.py:93} INFO -     raise exception
[2025-02-12T20:52:01.798+0000] {subprocess.py:93} INFO -   File "/home/***/.local/lib/python3.12/site-packages/sqlalchemy/pool/impl.py", line 143, in _do_get
[2025-02-12T20:52:01.798+0000] {subprocess.py:93} INFO -     return self._create_connection()
[2025-02-12T20:52:01.798+0000] {subprocess.py:93} INFO -            ^^^^^^^^^^^^^^^^^^^^^^^^^
[2025-02-12T20:52:01.799+0000] {subprocess.py:93} INFO -   File "/home/***/.local/lib/python3.12/site-packages/sqlalchemy/pool/base.py", line 273, in _create_connection
[2025-02-12T20:52:01.799+0000] {subprocess.py:93} INFO -     return _ConnectionRecord(self)
[2025-02-12T20:52:01.799+0000] {subprocess.py:93} INFO -            ^^^^^^^^^^^^^^^^^^^^^^^
[2025-02-12T20:52:01.800+0000] {subprocess.py:93} INFO -   File "/home/***/.local/lib/python3.12/site-packages/sqlalchemy/pool/base.py", line 388, in __init__
[2025-02-12T20:52:01.800+0000] {subprocess.py:93} INFO -     self.__connect()
[2025-02-12T20:52:01.800+0000] {subprocess.py:93} INFO -   File "/home/***/.local/lib/python3.12/site-packages/sqlalchemy/pool/base.py", line 690, in __connect
[2025-02-12T20:52:01.801+0000] {subprocess.py:93} INFO -     with util.safe_reraise():
[2025-02-12T20:52:01.801+0000] {subprocess.py:93} INFO -   File "/home/***/.local/lib/python3.12/site-packages/sqlalchemy/util/langhelpers.py", line 70, in __exit__
[2025-02-12T20:52:01.801+0000] {subprocess.py:93} INFO -     compat.raise_(
[2025-02-12T20:52:01.802+0000] {subprocess.py:93} INFO -   File "/home/***/.local/lib/python3.12/site-packages/sqlalchemy/util/compat.py", line 211, in raise_
[2025-02-12T20:52:01.802+0000] {subprocess.py:93} INFO -     raise exception
[2025-02-12T20:52:01.802+0000] {subprocess.py:93} INFO -   File "/home/***/.local/lib/python3.12/site-packages/sqlalchemy/pool/base.py", line 686, in __connect
[2025-02-12T20:52:01.802+0000] {subprocess.py:93} INFO -     self.dbapi_connection = connection = pool._invoke_creator(self)
[2025-02-12T20:52:01.803+0000] {subprocess.py:93} INFO -                                          ^^^^^^^^^^^^^^^^^^^^^^^^^^
[2025-02-12T20:52:01.803+0000] {subprocess.py:93} INFO -   File "/home/***/.local/lib/python3.12/site-packages/sqlalchemy/engine/create.py", line 574, in connect
[2025-02-12T20:52:01.803+0000] {subprocess.py:93} INFO -     return dialect.connect(*cargs, **cparams)
[2025-02-12T20:52:01.804+0000] {subprocess.py:93} INFO -            ^^^^^^^^^^^^^^^^^^^^^^^^^^^^^^^^^^
[2025-02-12T20:52:01.804+0000] {subprocess.py:93} INFO -   File "/home/***/.local/lib/python3.12/site-packages/sqlalchemy/engine/default.py", line 598, in connect
[2025-02-12T20:52:01.804+0000] {subprocess.py:93} INFO -     return self.dbapi.connect(*cargs, **cparams)
[2025-02-12T20:52:01.805+0000] {subprocess.py:93} INFO -            ^^^^^^^^^^^^^^^^^^^^^^^^^^^^^^^^^^^^^
[2025-02-12T20:52:01.805+0000] {subprocess.py:93} INFO -   File "/home/***/.local/lib/python3.12/site-packages/psycopg2/__init__.py", line 122, in connect
[2025-02-12T20:52:01.806+0000] {subprocess.py:93} INFO -     conn = _connect(dsn, connection_factory=connection_factory, **kwasync)
[2025-02-12T20:52:01.806+0000] {subprocess.py:93} INFO -            ^^^^^^^^^^^^^^^^^^^^^^^^^^^^^^^^^^^^^^^^^^^^^^^^^^^^^^^^^^^^^^^
[2025-02-12T20:52:01.806+0000] {subprocess.py:93} INFO - psycopg2.OperationalError: connection to server at "localhost" (::1), port 5432 failed: Connection refused
[2025-02-12T20:52:01.807+0000] {subprocess.py:93} INFO - 	Is the server running on that host and accepting TCP/IP connections?
[2025-02-12T20:52:01.807+0000] {subprocess.py:93} INFO - connection to server at "localhost" (127.0.0.1), port 5432 failed: Connection refused
[2025-02-12T20:52:01.807+0000] {subprocess.py:93} INFO - 	Is the server running on that host and accepting TCP/IP connections?
[2025-02-12T20:52:01.808+0000] {subprocess.py:93} INFO - 
[2025-02-12T20:52:01.808+0000] {subprocess.py:93} INFO - 
[2025-02-12T20:52:01.808+0000] {subprocess.py:93} INFO - The above exception was the direct cause of the following exception:
[2025-02-12T20:52:01.808+0000] {subprocess.py:93} INFO - 
[2025-02-12T20:52:01.809+0000] {subprocess.py:93} INFO - Traceback (most recent call last):
[2025-02-12T20:52:01.809+0000] {subprocess.py:93} INFO -   File "/opt/***/pipeline/main.py", line 88, in <module>
[2025-02-12T20:52:01.809+0000] {subprocess.py:93} INFO -     conn.insere_filmes(filme_df, 'filmes', genero_df, 'genero', 'filme_genero', 'omdb')
[2025-02-12T20:52:01.810+0000] {subprocess.py:93} INFO -   File "/opt/***/pipeline/connection.py", line 67, in insere_filmes
[2025-02-12T20:52:01.810+0000] {subprocess.py:93} INFO -     filmes_df.to_sql(filmes_table, self.engine, schema=schema, if_exists="append", index=False, \
[2025-02-12T20:52:01.810+0000] {subprocess.py:93} INFO -   File "/home/***/.local/lib/python3.12/site-packages/pandas/util/_decorators.py", line 333, in wrapper
[2025-02-12T20:52:01.810+0000] {subprocess.py:93} INFO -     return func(*args, **kwargs)
[2025-02-12T20:52:01.811+0000] {subprocess.py:93} INFO -            ^^^^^^^^^^^^^^^^^^^^^
[2025-02-12T20:52:01.811+0000] {subprocess.py:93} INFO -   File "/home/***/.local/lib/python3.12/site-packages/pandas/core/generic.py", line 3008, in to_sql
[2025-02-12T20:52:01.811+0000] {subprocess.py:93} INFO -     return sql.to_sql(
[2025-02-12T20:52:01.811+0000] {subprocess.py:93} INFO -            ^^^^^^^^^^^
[2025-02-12T20:52:01.812+0000] {subprocess.py:93} INFO -   File "/home/***/.local/lib/python3.12/site-packages/pandas/io/sql.py", line 787, in to_sql
[2025-02-12T20:52:01.812+0000] {subprocess.py:93} INFO -     with pandasSQL_builder(con, schema=schema, need_transaction=True) as pandas_sql:
[2025-02-12T20:52:01.812+0000] {subprocess.py:93} INFO -          ^^^^^^^^^^^^^^^^^^^^^^^^^^^^^^^^^^^^^^^^^^^^^^^^^^^^^^^^^^^^
[2025-02-12T20:52:01.812+0000] {subprocess.py:93} INFO -   File "/home/***/.local/lib/python3.12/site-packages/pandas/io/sql.py", line 851, in pandasSQL_builder
[2025-02-12T20:52:01.813+0000] {subprocess.py:93} INFO -     return SQLDatabase(con, schema, need_transaction)
[2025-02-12T20:52:01.813+0000] {subprocess.py:93} INFO -            ^^^^^^^^^^^^^^^^^^^^^^^^^^^^^^^^^^^^^^^^^^
[2025-02-12T20:52:01.813+0000] {subprocess.py:93} INFO -   File "/home/***/.local/lib/python3.12/site-packages/pandas/io/sql.py", line 1576, in __init__
[2025-02-12T20:52:01.814+0000] {subprocess.py:93} INFO -     con = self.exit_stack.enter_context(con.connect())
[2025-02-12T20:52:01.814+0000] {subprocess.py:93} INFO -                                         ^^^^^^^^^^^^^
[2025-02-12T20:52:01.814+0000] {subprocess.py:93} INFO -   File "/home/***/.local/lib/python3.12/site-packages/sqlalchemy/engine/base.py", line 3325, in connect
[2025-02-12T20:52:01.814+0000] {subprocess.py:93} INFO -     return self._connection_cls(self, close_with_result=close_with_result)
[2025-02-12T20:52:01.815+0000] {subprocess.py:93} INFO -            ^^^^^^^^^^^^^^^^^^^^^^^^^^^^^^^^^^^^^^^^^^^^^^^^^^^^^^^^^^^^^^^
[2025-02-12T20:52:01.815+0000] {subprocess.py:93} INFO -   File "/home/***/.local/lib/python3.12/site-packages/sqlalchemy/engine/base.py", line 96, in __init__
[2025-02-12T20:52:01.815+0000] {subprocess.py:93} INFO -     else engine.raw_connection()
[2025-02-12T20:52:01.815+0000] {subprocess.py:93} INFO -          ^^^^^^^^^^^^^^^^^^^^^^^
[2025-02-12T20:52:01.816+0000] {subprocess.py:93} INFO -   File "/home/***/.local/lib/python3.12/site-packages/sqlalchemy/engine/base.py", line 3404, in raw_connection
[2025-02-12T20:52:01.816+0000] {subprocess.py:93} INFO -     return self._wrap_pool_connect(self.pool.connect, _connection)
[2025-02-12T20:52:01.816+0000] {subprocess.py:93} INFO -            ^^^^^^^^^^^^^^^^^^^^^^^^^^^^^^^^^^^^^^^^^^^^^^^^^^^^^^^
[2025-02-12T20:52:01.816+0000] {subprocess.py:93} INFO -   File "/home/***/.local/lib/python3.12/site-packages/sqlalchemy/engine/base.py", line 3374, in _wrap_pool_connect
[2025-02-12T20:52:01.817+0000] {subprocess.py:93} INFO -     Connection._handle_dbapi_exception_noconnection(
[2025-02-12T20:52:01.817+0000] {subprocess.py:93} INFO -   File "/home/***/.local/lib/python3.12/site-packages/sqlalchemy/engine/base.py", line 2208, in _handle_dbapi_exception_noconnection
[2025-02-12T20:52:01.817+0000] {subprocess.py:93} INFO -     util.raise_(
[2025-02-12T20:52:01.817+0000] {subprocess.py:93} INFO -   File "/home/***/.local/lib/python3.12/site-packages/sqlalchemy/util/compat.py", line 211, in raise_
[2025-02-12T20:52:01.818+0000] {subprocess.py:93} INFO -     raise exception
[2025-02-12T20:52:01.818+0000] {subprocess.py:93} INFO -   File "/home/***/.local/lib/python3.12/site-packages/sqlalchemy/engine/base.py", line 3371, in _wrap_pool_connect
[2025-02-12T20:52:01.818+0000] {subprocess.py:93} INFO -     return fn()
[2025-02-12T20:52:01.819+0000] {subprocess.py:93} INFO -            ^^^^
[2025-02-12T20:52:01.819+0000] {subprocess.py:93} INFO -   File "/home/***/.local/lib/python3.12/site-packages/sqlalchemy/pool/base.py", line 327, in connect
[2025-02-12T20:52:01.819+0000] {subprocess.py:93} INFO -     return _ConnectionFairy._checkout(self)
[2025-02-12T20:52:01.819+0000] {subprocess.py:93} INFO -            ^^^^^^^^^^^^^^^^^^^^^^^^^^^^^^^^
[2025-02-12T20:52:01.820+0000] {subprocess.py:93} INFO -   File "/home/***/.local/lib/python3.12/site-packages/sqlalchemy/pool/base.py", line 894, in _checkout
[2025-02-12T20:52:01.820+0000] {subprocess.py:93} INFO -     fairy = _ConnectionRecord.checkout(pool)
[2025-02-12T20:52:01.820+0000] {subprocess.py:93} INFO -             ^^^^^^^^^^^^^^^^^^^^^^^^^^^^^^^^
[2025-02-12T20:52:01.821+0000] {subprocess.py:93} INFO -   File "/home/***/.local/lib/python3.12/site-packages/sqlalchemy/pool/base.py", line 493, in checkout
[2025-02-12T20:52:01.821+0000] {subprocess.py:93} INFO -     rec = pool._do_get()
[2025-02-12T20:52:01.821+0000] {subprocess.py:93} INFO -           ^^^^^^^^^^^^^^
[2025-02-12T20:52:01.821+0000] {subprocess.py:93} INFO -   File "/home/***/.local/lib/python3.12/site-packages/sqlalchemy/pool/impl.py", line 145, in _do_get
[2025-02-12T20:52:01.822+0000] {subprocess.py:93} INFO -     with util.safe_reraise():
[2025-02-12T20:52:01.822+0000] {subprocess.py:93} INFO -   File "/home/***/.local/lib/python3.12/site-packages/sqlalchemy/util/langhelpers.py", line 70, in __exit__
[2025-02-12T20:52:01.822+0000] {subprocess.py:93} INFO -     compat.raise_(
[2025-02-12T20:52:01.822+0000] {subprocess.py:93} INFO -   File "/home/***/.local/lib/python3.12/site-packages/sqlalchemy/util/compat.py", line 211, in raise_
[2025-02-12T20:52:01.823+0000] {subprocess.py:93} INFO -     raise exception
[2025-02-12T20:52:01.823+0000] {subprocess.py:93} INFO -   File "/home/***/.local/lib/python3.12/site-packages/sqlalchemy/pool/impl.py", line 143, in _do_get
[2025-02-12T20:52:01.823+0000] {subprocess.py:93} INFO -     return self._create_connection()
[2025-02-12T20:52:01.824+0000] {subprocess.py:93} INFO -            ^^^^^^^^^^^^^^^^^^^^^^^^^
[2025-02-12T20:52:01.824+0000] {subprocess.py:93} INFO -   File "/home/***/.local/lib/python3.12/site-packages/sqlalchemy/pool/base.py", line 273, in _create_connection
[2025-02-12T20:52:01.824+0000] {subprocess.py:93} INFO -     return _ConnectionRecord(self)
[2025-02-12T20:52:01.824+0000] {subprocess.py:93} INFO -            ^^^^^^^^^^^^^^^^^^^^^^^
[2025-02-12T20:52:01.825+0000] {subprocess.py:93} INFO -   File "/home/***/.local/lib/python3.12/site-packages/sqlalchemy/pool/base.py", line 388, in __init__
[2025-02-12T20:52:01.825+0000] {subprocess.py:93} INFO -     self.__connect()
[2025-02-12T20:52:01.825+0000] {subprocess.py:93} INFO -   File "/home/***/.local/lib/python3.12/site-packages/sqlalchemy/pool/base.py", line 690, in __connect
[2025-02-12T20:52:01.826+0000] {subprocess.py:93} INFO -     with util.safe_reraise():
[2025-02-12T20:52:01.826+0000] {subprocess.py:93} INFO -   File "/home/***/.local/lib/python3.12/site-packages/sqlalchemy/util/langhelpers.py", line 70, in __exit__
[2025-02-12T20:52:01.826+0000] {subprocess.py:93} INFO -     compat.raise_(
[2025-02-12T20:52:01.827+0000] {subprocess.py:93} INFO -   File "/home/***/.local/lib/python3.12/site-packages/sqlalchemy/util/compat.py", line 211, in raise_
[2025-02-12T20:52:01.827+0000] {subprocess.py:93} INFO -     raise exception
[2025-02-12T20:52:01.827+0000] {subprocess.py:93} INFO -   File "/home/***/.local/lib/python3.12/site-packages/sqlalchemy/pool/base.py", line 686, in __connect
[2025-02-12T20:52:01.827+0000] {subprocess.py:93} INFO -     self.dbapi_connection = connection = pool._invoke_creator(self)
[2025-02-12T20:52:01.828+0000] {subprocess.py:93} INFO -                                          ^^^^^^^^^^^^^^^^^^^^^^^^^^
[2025-02-12T20:52:01.828+0000] {subprocess.py:93} INFO -   File "/home/***/.local/lib/python3.12/site-packages/sqlalchemy/engine/create.py", line 574, in connect
[2025-02-12T20:52:01.828+0000] {subprocess.py:93} INFO -     return dialect.connect(*cargs, **cparams)
[2025-02-12T20:52:01.829+0000] {subprocess.py:93} INFO -            ^^^^^^^^^^^^^^^^^^^^^^^^^^^^^^^^^^
[2025-02-12T20:52:01.829+0000] {subprocess.py:93} INFO -   File "/home/***/.local/lib/python3.12/site-packages/sqlalchemy/engine/default.py", line 598, in connect
[2025-02-12T20:52:01.829+0000] {subprocess.py:93} INFO -     return self.dbapi.connect(*cargs, **cparams)
[2025-02-12T20:52:01.830+0000] {subprocess.py:93} INFO -            ^^^^^^^^^^^^^^^^^^^^^^^^^^^^^^^^^^^^^
[2025-02-12T20:52:01.830+0000] {subprocess.py:93} INFO -   File "/home/***/.local/lib/python3.12/site-packages/psycopg2/__init__.py", line 122, in connect
[2025-02-12T20:52:01.830+0000] {subprocess.py:93} INFO -     conn = _connect(dsn, connection_factory=connection_factory, **kwasync)
[2025-02-12T20:52:01.830+0000] {subprocess.py:93} INFO -            ^^^^^^^^^^^^^^^^^^^^^^^^^^^^^^^^^^^^^^^^^^^^^^^^^^^^^^^^^^^^^^^
[2025-02-12T20:52:01.831+0000] {subprocess.py:93} INFO - sqlalchemy.exc.OperationalError: (psycopg2.OperationalError) connection to server at "localhost" (::1), port 5432 failed: Connection refused
[2025-02-12T20:52:01.831+0000] {subprocess.py:93} INFO - 	Is the server running on that host and accepting TCP/IP connections?
[2025-02-12T20:52:01.831+0000] {subprocess.py:93} INFO - connection to server at "localhost" (127.0.0.1), port 5432 failed: Connection refused
[2025-02-12T20:52:01.831+0000] {subprocess.py:93} INFO - 	Is the server running on that host and accepting TCP/IP connections?
[2025-02-12T20:52:01.832+0000] {subprocess.py:93} INFO - 
[2025-02-12T20:52:01.832+0000] {subprocess.py:93} INFO - (Background on this error at: https://sqlalche.me/e/14/e3q8)
[2025-02-12T20:52:01.892+0000] {subprocess.py:97} INFO - Command exited with return code 1
[2025-02-12T20:52:01.893+0000] {taskinstance.py:441} INFO - ::group::Post task execution logs
[2025-02-12T20:52:01.903+0000] {taskinstance.py:2905} ERROR - Task failed with exception
Traceback (most recent call last):
  File "/home/airflow/.local/lib/python3.12/site-packages/airflow/models/taskinstance.py", line 465, in _execute_task
    result = _execute_callable(context=context, **execute_callable_kwargs)
             ^^^^^^^^^^^^^^^^^^^^^^^^^^^^^^^^^^^^^^^^^^^^^^^^^^^^^^^^^^^^^
  File "/home/airflow/.local/lib/python3.12/site-packages/airflow/models/taskinstance.py", line 432, in _execute_callable
    return execute_callable(context=context, **execute_callable_kwargs)
           ^^^^^^^^^^^^^^^^^^^^^^^^^^^^^^^^^^^^^^^^^^^^^^^^^^^^^^^^^^^^
  File "/home/airflow/.local/lib/python3.12/site-packages/airflow/models/baseoperator.py", line 400, in wrapper
    return func(self, *args, **kwargs)
           ^^^^^^^^^^^^^^^^^^^^^^^^^^^
  File "/home/airflow/.local/lib/python3.12/site-packages/airflow/operators/bash.py", line 243, in execute
    raise AirflowException(
airflow.exceptions.AirflowException: Bash command failed. The command returned a non-zero exit code 1.
[2025-02-12T20:52:01.906+0000] {taskinstance.py:1206} INFO - Marking task as UP_FOR_RETRY. dag_id=call_omdb_api, task_id=teste, run_id=scheduled__2025-02-12T20:51:00+00:00, execution_date=20250212T205100, start_date=20250212T205200, end_date=20250212T205201
[2025-02-12T20:52:01.919+0000] {standard_task_runner.py:110} ERROR - Failed to execute job 157 for task teste (Bash command failed. The command returned a non-zero exit code 1.; 955)
[2025-02-12T20:52:01.930+0000] {local_task_job_runner.py:240} INFO - Task exited with return code 1
[2025-02-12T20:52:01.944+0000] {taskinstance.py:3498} INFO - 0 downstream tasks scheduled from follow-on schedule check
[2025-02-12T20:52:01.946+0000] {local_task_job_runner.py:222} INFO - ::endgroup::
