[2025-02-12T20:54:03.843+0000] {local_task_job_runner.py:120} INFO - ::group::Pre task execution logs
[2025-02-12T20:54:03.862+0000] {taskinstance.py:2076} INFO - Dependencies all met for dep_context=non-requeueable deps ti=<TaskInstance: call_omdb_api.teste scheduled__2025-02-12T20:52:00+00:00 [queued]>
[2025-02-12T20:54:03.868+0000] {taskinstance.py:2076} INFO - Dependencies all met for dep_context=requeueable deps ti=<TaskInstance: call_omdb_api.teste scheduled__2025-02-12T20:52:00+00:00 [queued]>
[2025-02-12T20:54:03.868+0000] {taskinstance.py:2306} INFO - Starting attempt 2 of 2
[2025-02-12T20:54:03.880+0000] {taskinstance.py:2330} INFO - Executing <Task(BashOperator): teste> on 2025-02-12 20:52:00+00:00
[2025-02-12T20:54:03.885+0000] {warnings.py:110} WARNING - /home/***/.local/lib/python3.12/site-packages/***/task/task_runner/standard_task_runner.py:61: DeprecationWarning: This process (pid=1087) is multi-threaded, use of fork() may lead to deadlocks in the child.
  pid = os.fork()

[2025-02-12T20:54:03.886+0000] {standard_task_runner.py:63} INFO - Started process 1088 to run task
[2025-02-12T20:54:03.886+0000] {standard_task_runner.py:90} INFO - Running: ['***', 'tasks', 'run', 'call_omdb_api', 'teste', 'scheduled__2025-02-12T20:52:00+00:00', '--job-id', '164', '--raw', '--subdir', 'DAGS_FOLDER/call_api.py', '--cfg-path', '/tmp/tmpwthpdzcj']
[2025-02-12T20:54:03.887+0000] {standard_task_runner.py:91} INFO - Job 164: Subtask teste
[2025-02-12T20:54:03.925+0000] {task_command.py:426} INFO - Running <TaskInstance: call_omdb_api.teste scheduled__2025-02-12T20:52:00+00:00 [running]> on host a7cb053280af
[2025-02-12T20:54:03.994+0000] {taskinstance.py:2648} INFO - Exporting env vars: AIRFLOW_CTX_DAG_OWNER='Celso Cazetto' AIRFLOW_CTX_DAG_ID='call_omdb_api' AIRFLOW_CTX_TASK_ID='teste' AIRFLOW_CTX_EXECUTION_DATE='2025-02-12T20:52:00+00:00' AIRFLOW_CTX_TRY_NUMBER='2' AIRFLOW_CTX_DAG_RUN_ID='scheduled__2025-02-12T20:52:00+00:00'
[2025-02-12T20:54:03.995+0000] {taskinstance.py:430} INFO - ::endgroup::
[2025-02-12T20:54:04.006+0000] {subprocess.py:63} INFO - Tmp dir root location: /tmp
[2025-02-12T20:54:04.007+0000] {subprocess.py:75} INFO - Running command: ['/usr/bin/bash', '-c', 'python /opt/***/pipeline/main.py']
[2025-02-12T20:54:04.014+0000] {subprocess.py:86} INFO - Output:
[2025-02-12T20:54:04.913+0000] {subprocess.py:93} INFO - 2025-02-12 20:54:04,913 - INFO - ESTOU RODANDO ESSA PORRA
[2025-02-12T20:54:04.914+0000] {subprocess.py:93} INFO - 2025-02-12 20:54:04,914 - INFO - Carregando o arquivo de configuração
[2025-02-12T20:54:04.915+0000] {subprocess.py:93} INFO - 2025-02-12 20:54:04,915 - INFO - Buscando os dados de filme do ID:tt0499549
[2025-02-12T20:54:05.026+0000] {subprocess.py:93} INFO - 2025-02-12 20:54:05,026 - INFO - Dados da API carregados com sucesso
[2025-02-12T20:54:05.027+0000] {subprocess.py:93} INFO - 2025-02-12 20:54:05,026 - INFO - Iniciando transformação dos dados.
[2025-02-12T20:54:05.034+0000] {subprocess.py:93} INFO - 2025-02-12 20:54:05,034 - INFO - Estabelecendo conexão com o banco de dados:
[2025-02-12T20:54:05.063+0000] {subprocess.py:93} INFO - 2025-02-12 20:54:05,063 - INFO - Conexão estabelecida com sucesso.
[2025-02-12T20:54:05.081+0000] {subprocess.py:93} INFO - 2025-02-12 20:54:05,081 - INFO - Iniciando o inserção na tabela: omdb.filmes
[2025-02-12T20:54:05.085+0000] {subprocess.py:93} INFO - 2025-02-12 20:54:05,084 - INFO - 0 Inseridos na tabela omdb.filmes
[2025-02-12T20:54:05.088+0000] {subprocess.py:93} INFO - 2025-02-12 20:54:05,088 - INFO - Iniciando o inserção na tabela: omdb.genero
[2025-02-12T20:54:05.091+0000] {subprocess.py:93} INFO - 2025-02-12 20:54:05,091 - INFO - 0 Inseridos na tabela omdb.genero
[2025-02-12T20:54:05.100+0000] {subprocess.py:93} INFO - 2025-02-12 20:54:05,100 - INFO - Iniciando o inserção na tabela: omdb.filme_genero
[2025-02-12T20:54:05.102+0000] {subprocess.py:93} INFO - 2025-02-12 20:54:05,102 - INFO - 0 Inseridos na tabela omdb.filme_genero
[2025-02-12T20:54:05.103+0000] {subprocess.py:93} INFO - Traceback (most recent call last):
[2025-02-12T20:54:05.104+0000] {subprocess.py:93} INFO -   File "/opt/***/pipeline/main.py", line 88, in <module>
[2025-02-12T20:54:05.105+0000] {subprocess.py:93} INFO -     conn.insere_filmes(filme_df, 'filmes', genero_df, 'genero', 'filme_genero', 'omdb')
[2025-02-12T20:54:05.106+0000] {subprocess.py:93} INFO -   File "/opt/***/pipeline/connection.py", line 79, in insere_filmes
[2025-02-12T20:54:05.107+0000] {subprocess.py:93} INFO -     self.close()
[2025-02-12T20:54:05.107+0000] {subprocess.py:93} INFO -   File "/opt/***/pipeline/connection.py", line 36, in close
[2025-02-12T20:54:05.109+0000] {subprocess.py:93} INFO -     self.conn.commit()
[2025-02-12T20:54:05.109+0000] {subprocess.py:93} INFO -     ^^^^^^^^^^^^^^^^
[2025-02-12T20:54:05.109+0000] {subprocess.py:93} INFO - AttributeError: 'Connection' object has no attribute 'commit'
[2025-02-12T20:54:05.213+0000] {subprocess.py:97} INFO - Command exited with return code 1
[2025-02-12T20:54:05.213+0000] {taskinstance.py:441} INFO - ::group::Post task execution logs
[2025-02-12T20:54:05.221+0000] {taskinstance.py:2905} ERROR - Task failed with exception
Traceback (most recent call last):
  File "/home/airflow/.local/lib/python3.12/site-packages/airflow/models/taskinstance.py", line 465, in _execute_task
    result = _execute_callable(context=context, **execute_callable_kwargs)
             ^^^^^^^^^^^^^^^^^^^^^^^^^^^^^^^^^^^^^^^^^^^^^^^^^^^^^^^^^^^^^
  File "/home/airflow/.local/lib/python3.12/site-packages/airflow/models/taskinstance.py", line 432, in _execute_callable
    return execute_callable(context=context, **execute_callable_kwargs)
           ^^^^^^^^^^^^^^^^^^^^^^^^^^^^^^^^^^^^^^^^^^^^^^^^^^^^^^^^^^^^
  File "/home/airflow/.local/lib/python3.12/site-packages/airflow/models/baseoperator.py", line 400, in wrapper
    return func(self, *args, **kwargs)
           ^^^^^^^^^^^^^^^^^^^^^^^^^^^
  File "/home/airflow/.local/lib/python3.12/site-packages/airflow/operators/bash.py", line 243, in execute
    raise AirflowException(
airflow.exceptions.AirflowException: Bash command failed. The command returned a non-zero exit code 1.
[2025-02-12T20:54:05.225+0000] {taskinstance.py:1206} INFO - Marking task as FAILED. dag_id=call_omdb_api, task_id=teste, run_id=scheduled__2025-02-12T20:52:00+00:00, execution_date=20250212T205200, start_date=20250212T205403, end_date=20250212T205405
[2025-02-12T20:54:05.236+0000] {standard_task_runner.py:110} ERROR - Failed to execute job 164 for task teste (Bash command failed. The command returned a non-zero exit code 1.; 1088)
[2025-02-12T20:54:05.263+0000] {local_task_job_runner.py:240} INFO - Task exited with return code 1
[2025-02-12T20:54:05.277+0000] {taskinstance.py:3498} INFO - 0 downstream tasks scheduled from follow-on schedule check
[2025-02-12T20:54:05.279+0000] {local_task_job_runner.py:222} INFO - ::endgroup::
