[2025-02-12T20:12:01.278+0000] {local_task_job_runner.py:120} INFO - ::group::Pre task execution logs
[2025-02-12T20:12:01.294+0000] {taskinstance.py:2076} INFO - Dependencies all met for dep_context=non-requeueable deps ti=<TaskInstance: call_omdb_api.teste scheduled__2025-02-12T20:11:00+00:00 [queued]>
[2025-02-12T20:12:01.299+0000] {taskinstance.py:2076} INFO - Dependencies all met for dep_context=requeueable deps ti=<TaskInstance: call_omdb_api.teste scheduled__2025-02-12T20:11:00+00:00 [queued]>
[2025-02-12T20:12:01.300+0000] {taskinstance.py:2306} INFO - Starting attempt 1 of 2
[2025-02-12T20:12:01.312+0000] {taskinstance.py:2330} INFO - Executing <Task(BashOperator): teste> on 2025-02-12 20:11:00+00:00
[2025-02-12T20:12:01.316+0000] {warnings.py:110} WARNING - /home/***/.local/lib/python3.12/site-packages/***/task/task_runner/standard_task_runner.py:61: DeprecationWarning: This process (pid=936) is multi-threaded, use of fork() may lead to deadlocks in the child.
  pid = os.fork()

[2025-02-12T20:12:01.318+0000] {standard_task_runner.py:63} INFO - Started process 937 to run task
[2025-02-12T20:12:01.318+0000] {standard_task_runner.py:90} INFO - Running: ['***', 'tasks', 'run', 'call_omdb_api', 'teste', 'scheduled__2025-02-12T20:11:00+00:00', '--job-id', '84', '--raw', '--subdir', 'DAGS_FOLDER/call_api.py', '--cfg-path', '/tmp/tmpmjztyl3y']
[2025-02-12T20:12:01.319+0000] {standard_task_runner.py:91} INFO - Job 84: Subtask teste
[2025-02-12T20:12:01.354+0000] {task_command.py:426} INFO - Running <TaskInstance: call_omdb_api.teste scheduled__2025-02-12T20:11:00+00:00 [running]> on host f82bf6a6274c
[2025-02-12T20:12:01.421+0000] {taskinstance.py:2648} INFO - Exporting env vars: AIRFLOW_CTX_DAG_OWNER='Celso Cazetto' AIRFLOW_CTX_DAG_ID='call_omdb_api' AIRFLOW_CTX_TASK_ID='teste' AIRFLOW_CTX_EXECUTION_DATE='2025-02-12T20:11:00+00:00' AIRFLOW_CTX_TRY_NUMBER='1' AIRFLOW_CTX_DAG_RUN_ID='scheduled__2025-02-12T20:11:00+00:00'
[2025-02-12T20:12:01.422+0000] {taskinstance.py:430} INFO - ::endgroup::
[2025-02-12T20:12:01.432+0000] {subprocess.py:63} INFO - Tmp dir root location: /tmp
[2025-02-12T20:12:01.434+0000] {subprocess.py:75} INFO - Running command: ['/usr/bin/bash', '-c', 'python ~/***/pipeline/.main.py']
[2025-02-12T20:12:01.443+0000] {subprocess.py:86} INFO - Output:
[2025-02-12T20:12:01.487+0000] {subprocess.py:93} INFO - python: can't open file '/home/***/***/pipeline/.main.py': [Errno 2] No such file or directory
[2025-02-12T20:12:01.490+0000] {subprocess.py:97} INFO - Command exited with return code 2
[2025-02-12T20:12:01.492+0000] {taskinstance.py:441} INFO - ::group::Post task execution logs
[2025-02-12T20:12:01.500+0000] {taskinstance.py:2905} ERROR - Task failed with exception
Traceback (most recent call last):
  File "/home/airflow/.local/lib/python3.12/site-packages/airflow/models/taskinstance.py", line 465, in _execute_task
    result = _execute_callable(context=context, **execute_callable_kwargs)
             ^^^^^^^^^^^^^^^^^^^^^^^^^^^^^^^^^^^^^^^^^^^^^^^^^^^^^^^^^^^^^
  File "/home/airflow/.local/lib/python3.12/site-packages/airflow/models/taskinstance.py", line 432, in _execute_callable
    return execute_callable(context=context, **execute_callable_kwargs)
           ^^^^^^^^^^^^^^^^^^^^^^^^^^^^^^^^^^^^^^^^^^^^^^^^^^^^^^^^^^^^
  File "/home/airflow/.local/lib/python3.12/site-packages/airflow/models/baseoperator.py", line 400, in wrapper
    return func(self, *args, **kwargs)
           ^^^^^^^^^^^^^^^^^^^^^^^^^^^
  File "/home/airflow/.local/lib/python3.12/site-packages/airflow/operators/bash.py", line 243, in execute
    raise AirflowException(
airflow.exceptions.AirflowException: Bash command failed. The command returned a non-zero exit code 2.
[2025-02-12T20:12:01.503+0000] {taskinstance.py:1206} INFO - Marking task as UP_FOR_RETRY. dag_id=call_omdb_api, task_id=teste, run_id=scheduled__2025-02-12T20:11:00+00:00, execution_date=20250212T201100, start_date=20250212T201201, end_date=20250212T201201
[2025-02-12T20:12:01.513+0000] {standard_task_runner.py:110} ERROR - Failed to execute job 84 for task teste (Bash command failed. The command returned a non-zero exit code 2.; 937)
[2025-02-12T20:12:01.531+0000] {local_task_job_runner.py:240} INFO - Task exited with return code 1
[2025-02-12T20:12:01.544+0000] {taskinstance.py:3498} INFO - 0 downstream tasks scheduled from follow-on schedule check
[2025-02-12T20:12:01.546+0000] {local_task_job_runner.py:222} INFO - ::endgroup::
