[2025-02-12T20:50:00.684+0000] {local_task_job_runner.py:120} INFO - ::group::Pre task execution logs
[2025-02-12T20:50:00.704+0000] {taskinstance.py:2076} INFO - Dependencies all met for dep_context=non-requeueable deps ti=<TaskInstance: call_omdb_api.teste scheduled__2025-02-12T20:49:00+00:00 [queued]>
[2025-02-12T20:50:00.714+0000] {taskinstance.py:2076} INFO - Dependencies all met for dep_context=requeueable deps ti=<TaskInstance: call_omdb_api.teste scheduled__2025-02-12T20:49:00+00:00 [queued]>
[2025-02-12T20:50:00.715+0000] {taskinstance.py:2306} INFO - Starting attempt 1 of 2
[2025-02-12T20:50:00.732+0000] {taskinstance.py:2330} INFO - Executing <Task(BashOperator): teste> on 2025-02-12 20:49:00+00:00
[2025-02-12T20:50:00.736+0000] {warnings.py:110} WARNING - /home/***/.local/lib/python3.12/site-packages/***/task/task_runner/standard_task_runner.py:61: DeprecationWarning: This process (pid=866) is multi-threaded, use of fork() may lead to deadlocks in the child.
  pid = os.fork()

[2025-02-12T20:50:00.737+0000] {standard_task_runner.py:63} INFO - Started process 867 to run task
[2025-02-12T20:50:00.738+0000] {standard_task_runner.py:90} INFO - Running: ['***', 'tasks', 'run', 'call_omdb_api', 'teste', 'scheduled__2025-02-12T20:49:00+00:00', '--job-id', '153', '--raw', '--subdir', 'DAGS_FOLDER/call_api.py', '--cfg-path', '/tmp/tmpe1is8n54']
[2025-02-12T20:50:00.739+0000] {standard_task_runner.py:91} INFO - Job 153: Subtask teste
[2025-02-12T20:50:00.777+0000] {task_command.py:426} INFO - Running <TaskInstance: call_omdb_api.teste scheduled__2025-02-12T20:49:00+00:00 [running]> on host a7cb053280af
[2025-02-12T20:50:00.856+0000] {taskinstance.py:2648} INFO - Exporting env vars: AIRFLOW_CTX_DAG_OWNER='Celso Cazetto' AIRFLOW_CTX_DAG_ID='call_omdb_api' AIRFLOW_CTX_TASK_ID='teste' AIRFLOW_CTX_EXECUTION_DATE='2025-02-12T20:49:00+00:00' AIRFLOW_CTX_TRY_NUMBER='1' AIRFLOW_CTX_DAG_RUN_ID='scheduled__2025-02-12T20:49:00+00:00'
[2025-02-12T20:50:00.857+0000] {taskinstance.py:430} INFO - ::endgroup::
[2025-02-12T20:50:00.867+0000] {subprocess.py:63} INFO - Tmp dir root location: /tmp
[2025-02-12T20:50:00.868+0000] {subprocess.py:75} INFO - Running command: ['/usr/bin/bash', '-c', 'python /opt/***/pipeline/main.py']
[2025-02-12T20:50:00.876+0000] {subprocess.py:86} INFO - Output:
[2025-02-12T20:50:01.815+0000] {subprocess.py:93} INFO - 2025-02-12 20:50:01,814 - INFO - ESTOU RODANDO ESSA PORRA
[2025-02-12T20:50:01.816+0000] {subprocess.py:93} INFO - 2025-02-12 20:50:01,816 - INFO - Carregando o arquivo de configuração
[2025-02-12T20:50:01.817+0000] {subprocess.py:93} INFO - 2025-02-12 20:50:01,817 - INFO - Buscando os dados de filme do ID:tt0499549
[2025-02-12T20:50:01.928+0000] {subprocess.py:93} INFO - 2025-02-12 20:50:01,928 - INFO - Dados da API carregados com sucesso
[2025-02-12T20:50:01.929+0000] {subprocess.py:93} INFO - 2025-02-12 20:50:01,928 - INFO - Iniciando transformação dos dados.
[2025-02-12T20:50:01.936+0000] {subprocess.py:93} INFO - 2025-02-12 20:50:01,936 - INFO - Estabelecendo conexão com o banco de dados:
[2025-02-12T20:50:01.947+0000] {subprocess.py:93} INFO - 2025-02-12 20:50:01,947 - ERROR - Não foi possivel estabelecer a conexão com o banco de dados: (psycopg2.OperationalError) connection to server at "localhost" (::1), port 5432 failed: Connection refused
[2025-02-12T20:50:01.948+0000] {subprocess.py:93} INFO - 	Is the server running on that host and accepting TCP/IP connections?
[2025-02-12T20:50:01.948+0000] {subprocess.py:93} INFO - connection to server at "localhost" (127.0.0.1), port 5432 failed: Connection refused
[2025-02-12T20:50:01.948+0000] {subprocess.py:93} INFO - 	Is the server running on that host and accepting TCP/IP connections?
[2025-02-12T20:50:01.948+0000] {subprocess.py:93} INFO - 
[2025-02-12T20:50:01.949+0000] {subprocess.py:93} INFO - (Background on this error at: https://sqlalche.me/e/14/e3q8)
[2025-02-12T20:50:01.951+0000] {subprocess.py:93} INFO - Traceback (most recent call last):
[2025-02-12T20:50:01.951+0000] {subprocess.py:93} INFO -   File "/home/***/.local/lib/python3.12/site-packages/sqlalchemy/engine/base.py", line 3371, in _wrap_pool_connect
[2025-02-12T20:50:01.951+0000] {subprocess.py:93} INFO -     return fn()
[2025-02-12T20:50:01.952+0000] {subprocess.py:93} INFO -            ^^^^
[2025-02-12T20:50:01.952+0000] {subprocess.py:93} INFO -   File "/home/***/.local/lib/python3.12/site-packages/sqlalchemy/pool/base.py", line 327, in connect
[2025-02-12T20:50:01.952+0000] {subprocess.py:93} INFO -     return _ConnectionFairy._checkout(self)
[2025-02-12T20:50:01.952+0000] {subprocess.py:93} INFO -            ^^^^^^^^^^^^^^^^^^^^^^^^^^^^^^^^
[2025-02-12T20:50:01.953+0000] {subprocess.py:93} INFO -   File "/home/***/.local/lib/python3.12/site-packages/sqlalchemy/pool/base.py", line 894, in _checkout
[2025-02-12T20:50:01.953+0000] {subprocess.py:93} INFO -     fairy = _ConnectionRecord.checkout(pool)
[2025-02-12T20:50:01.953+0000] {subprocess.py:93} INFO -             ^^^^^^^^^^^^^^^^^^^^^^^^^^^^^^^^
[2025-02-12T20:50:01.954+0000] {subprocess.py:93} INFO -   File "/home/***/.local/lib/python3.12/site-packages/sqlalchemy/pool/base.py", line 493, in checkout
[2025-02-12T20:50:01.954+0000] {subprocess.py:93} INFO -     rec = pool._do_get()
[2025-02-12T20:50:01.954+0000] {subprocess.py:93} INFO -           ^^^^^^^^^^^^^^
[2025-02-12T20:50:01.955+0000] {subprocess.py:93} INFO -   File "/home/***/.local/lib/python3.12/site-packages/sqlalchemy/pool/impl.py", line 145, in _do_get
[2025-02-12T20:50:01.955+0000] {subprocess.py:93} INFO -     with util.safe_reraise():
[2025-02-12T20:50:01.955+0000] {subprocess.py:93} INFO -   File "/home/***/.local/lib/python3.12/site-packages/sqlalchemy/util/langhelpers.py", line 70, in __exit__
[2025-02-12T20:50:01.956+0000] {subprocess.py:93} INFO -     compat.raise_(
[2025-02-12T20:50:01.956+0000] {subprocess.py:93} INFO -   File "/home/***/.local/lib/python3.12/site-packages/sqlalchemy/util/compat.py", line 211, in raise_
[2025-02-12T20:50:01.957+0000] {subprocess.py:93} INFO -     raise exception
[2025-02-12T20:50:01.957+0000] {subprocess.py:93} INFO -   File "/home/***/.local/lib/python3.12/site-packages/sqlalchemy/pool/impl.py", line 143, in _do_get
[2025-02-12T20:50:01.957+0000] {subprocess.py:93} INFO -     return self._create_connection()
[2025-02-12T20:50:01.957+0000] {subprocess.py:93} INFO -            ^^^^^^^^^^^^^^^^^^^^^^^^^
[2025-02-12T20:50:01.958+0000] {subprocess.py:93} INFO -   File "/home/***/.local/lib/python3.12/site-packages/sqlalchemy/pool/base.py", line 273, in _create_connection
[2025-02-12T20:50:01.958+0000] {subprocess.py:93} INFO -     return _ConnectionRecord(self)
[2025-02-12T20:50:01.958+0000] {subprocess.py:93} INFO -            ^^^^^^^^^^^^^^^^^^^^^^^
[2025-02-12T20:50:01.959+0000] {subprocess.py:93} INFO -   File "/home/***/.local/lib/python3.12/site-packages/sqlalchemy/pool/base.py", line 388, in __init__
[2025-02-12T20:50:01.959+0000] {subprocess.py:93} INFO -     self.__connect()
[2025-02-12T20:50:01.959+0000] {subprocess.py:93} INFO -   File "/home/***/.local/lib/python3.12/site-packages/sqlalchemy/pool/base.py", line 690, in __connect
[2025-02-12T20:50:01.959+0000] {subprocess.py:93} INFO -     with util.safe_reraise():
[2025-02-12T20:50:01.960+0000] {subprocess.py:93} INFO -   File "/home/***/.local/lib/python3.12/site-packages/sqlalchemy/util/langhelpers.py", line 70, in __exit__
[2025-02-12T20:50:01.960+0000] {subprocess.py:93} INFO -     compat.raise_(
[2025-02-12T20:50:01.960+0000] {subprocess.py:93} INFO -   File "/home/***/.local/lib/python3.12/site-packages/sqlalchemy/util/compat.py", line 211, in raise_
[2025-02-12T20:50:01.961+0000] {subprocess.py:93} INFO -     raise exception
[2025-02-12T20:50:01.961+0000] {subprocess.py:93} INFO -   File "/home/***/.local/lib/python3.12/site-packages/sqlalchemy/pool/base.py", line 686, in __connect
[2025-02-12T20:50:01.961+0000] {subprocess.py:93} INFO -     self.dbapi_connection = connection = pool._invoke_creator(self)
[2025-02-12T20:50:01.961+0000] {subprocess.py:93} INFO -                                          ^^^^^^^^^^^^^^^^^^^^^^^^^^
[2025-02-12T20:50:01.962+0000] {subprocess.py:93} INFO -   File "/home/***/.local/lib/python3.12/site-packages/sqlalchemy/engine/create.py", line 574, in connect
[2025-02-12T20:50:01.962+0000] {subprocess.py:93} INFO -     return dialect.connect(*cargs, **cparams)
[2025-02-12T20:50:01.962+0000] {subprocess.py:93} INFO -            ^^^^^^^^^^^^^^^^^^^^^^^^^^^^^^^^^^
[2025-02-12T20:50:01.962+0000] {subprocess.py:93} INFO -   File "/home/***/.local/lib/python3.12/site-packages/sqlalchemy/engine/default.py", line 598, in connect
[2025-02-12T20:50:01.963+0000] {subprocess.py:93} INFO -     return self.dbapi.connect(*cargs, **cparams)
[2025-02-12T20:50:01.963+0000] {subprocess.py:93} INFO -            ^^^^^^^^^^^^^^^^^^^^^^^^^^^^^^^^^^^^^
[2025-02-12T20:50:01.963+0000] {subprocess.py:93} INFO -   File "/home/***/.local/lib/python3.12/site-packages/psycopg2/__init__.py", line 122, in connect
[2025-02-12T20:50:01.964+0000] {subprocess.py:93} INFO -     conn = _connect(dsn, connection_factory=connection_factory, **kwasync)
[2025-02-12T20:50:01.964+0000] {subprocess.py:93} INFO -            ^^^^^^^^^^^^^^^^^^^^^^^^^^^^^^^^^^^^^^^^^^^^^^^^^^^^^^^^^^^^^^^
[2025-02-12T20:50:01.965+0000] {subprocess.py:93} INFO - psycopg2.OperationalError: connection to server at "localhost" (::1), port 5432 failed: Connection refused
[2025-02-12T20:50:01.965+0000] {subprocess.py:93} INFO - 	Is the server running on that host and accepting TCP/IP connections?
[2025-02-12T20:50:01.965+0000] {subprocess.py:93} INFO - connection to server at "localhost" (127.0.0.1), port 5432 failed: Connection refused
[2025-02-12T20:50:01.965+0000] {subprocess.py:93} INFO - 	Is the server running on that host and accepting TCP/IP connections?
[2025-02-12T20:50:01.966+0000] {subprocess.py:93} INFO - 
[2025-02-12T20:50:01.966+0000] {subprocess.py:93} INFO - 
[2025-02-12T20:50:01.966+0000] {subprocess.py:93} INFO - The above exception was the direct cause of the following exception:
[2025-02-12T20:50:01.967+0000] {subprocess.py:93} INFO - 
[2025-02-12T20:50:01.967+0000] {subprocess.py:93} INFO - Traceback (most recent call last):
[2025-02-12T20:50:01.967+0000] {subprocess.py:93} INFO -   File "/opt/***/pipeline/main.py", line 88, in <module>
[2025-02-12T20:50:01.968+0000] {subprocess.py:93} INFO -     conn.insere_filmes(filme_df, 'filmes', genero_df, 'genero', 'filme_genero', 'omdb')
[2025-02-12T20:50:01.968+0000] {subprocess.py:93} INFO -   File "/opt/***/pipeline/connection.py", line 67, in insere_filmes
[2025-02-12T20:50:01.968+0000] {subprocess.py:93} INFO -     filmes_df.to_sql(filmes_table, self.engine, schema=schema, if_exists="append", index=False, \
[2025-02-12T20:50:01.969+0000] {subprocess.py:93} INFO -   File "/home/***/.local/lib/python3.12/site-packages/pandas/util/_decorators.py", line 333, in wrapper
[2025-02-12T20:50:01.969+0000] {subprocess.py:93} INFO -     return func(*args, **kwargs)
[2025-02-12T20:50:01.969+0000] {subprocess.py:93} INFO -            ^^^^^^^^^^^^^^^^^^^^^
[2025-02-12T20:50:01.970+0000] {subprocess.py:93} INFO -   File "/home/***/.local/lib/python3.12/site-packages/pandas/core/generic.py", line 3008, in to_sql
[2025-02-12T20:50:01.970+0000] {subprocess.py:93} INFO -     return sql.to_sql(
[2025-02-12T20:50:01.970+0000] {subprocess.py:93} INFO -            ^^^^^^^^^^^
[2025-02-12T20:50:01.971+0000] {subprocess.py:93} INFO -   File "/home/***/.local/lib/python3.12/site-packages/pandas/io/sql.py", line 787, in to_sql
[2025-02-12T20:50:01.971+0000] {subprocess.py:93} INFO -     with pandasSQL_builder(con, schema=schema, need_transaction=True) as pandas_sql:
[2025-02-12T20:50:01.971+0000] {subprocess.py:93} INFO -          ^^^^^^^^^^^^^^^^^^^^^^^^^^^^^^^^^^^^^^^^^^^^^^^^^^^^^^^^^^^^
[2025-02-12T20:50:01.972+0000] {subprocess.py:93} INFO -   File "/home/***/.local/lib/python3.12/site-packages/pandas/io/sql.py", line 851, in pandasSQL_builder
[2025-02-12T20:50:01.972+0000] {subprocess.py:93} INFO -     return SQLDatabase(con, schema, need_transaction)
[2025-02-12T20:50:01.972+0000] {subprocess.py:93} INFO -            ^^^^^^^^^^^^^^^^^^^^^^^^^^^^^^^^^^^^^^^^^^
[2025-02-12T20:50:01.973+0000] {subprocess.py:93} INFO -   File "/home/***/.local/lib/python3.12/site-packages/pandas/io/sql.py", line 1576, in __init__
[2025-02-12T20:50:01.973+0000] {subprocess.py:93} INFO -     con = self.exit_stack.enter_context(con.connect())
[2025-02-12T20:50:01.973+0000] {subprocess.py:93} INFO -                                         ^^^^^^^^^^^^^
[2025-02-12T20:50:01.974+0000] {subprocess.py:93} INFO -   File "/home/***/.local/lib/python3.12/site-packages/sqlalchemy/engine/base.py", line 3325, in connect
[2025-02-12T20:50:01.974+0000] {subprocess.py:93} INFO -     return self._connection_cls(self, close_with_result=close_with_result)
[2025-02-12T20:50:01.974+0000] {subprocess.py:93} INFO -            ^^^^^^^^^^^^^^^^^^^^^^^^^^^^^^^^^^^^^^^^^^^^^^^^^^^^^^^^^^^^^^^
[2025-02-12T20:50:01.974+0000] {subprocess.py:93} INFO -   File "/home/***/.local/lib/python3.12/site-packages/sqlalchemy/engine/base.py", line 96, in __init__
[2025-02-12T20:50:01.975+0000] {subprocess.py:93} INFO -     else engine.raw_connection()
[2025-02-12T20:50:01.975+0000] {subprocess.py:93} INFO -          ^^^^^^^^^^^^^^^^^^^^^^^
[2025-02-12T20:50:01.975+0000] {subprocess.py:93} INFO -   File "/home/***/.local/lib/python3.12/site-packages/sqlalchemy/engine/base.py", line 3404, in raw_connection
[2025-02-12T20:50:01.975+0000] {subprocess.py:93} INFO -     return self._wrap_pool_connect(self.pool.connect, _connection)
[2025-02-12T20:50:01.976+0000] {subprocess.py:93} INFO -            ^^^^^^^^^^^^^^^^^^^^^^^^^^^^^^^^^^^^^^^^^^^^^^^^^^^^^^^
[2025-02-12T20:50:01.976+0000] {subprocess.py:93} INFO -   File "/home/***/.local/lib/python3.12/site-packages/sqlalchemy/engine/base.py", line 3374, in _wrap_pool_connect
[2025-02-12T20:50:01.976+0000] {subprocess.py:93} INFO -     Connection._handle_dbapi_exception_noconnection(
[2025-02-12T20:50:01.976+0000] {subprocess.py:93} INFO -   File "/home/***/.local/lib/python3.12/site-packages/sqlalchemy/engine/base.py", line 2208, in _handle_dbapi_exception_noconnection
[2025-02-12T20:50:01.977+0000] {subprocess.py:93} INFO -     util.raise_(
[2025-02-12T20:50:01.977+0000] {subprocess.py:93} INFO -   File "/home/***/.local/lib/python3.12/site-packages/sqlalchemy/util/compat.py", line 211, in raise_
[2025-02-12T20:50:01.977+0000] {subprocess.py:93} INFO -     raise exception
[2025-02-12T20:50:01.978+0000] {subprocess.py:93} INFO -   File "/home/***/.local/lib/python3.12/site-packages/sqlalchemy/engine/base.py", line 3371, in _wrap_pool_connect
[2025-02-12T20:50:01.978+0000] {subprocess.py:93} INFO -     return fn()
[2025-02-12T20:50:01.978+0000] {subprocess.py:93} INFO -            ^^^^
[2025-02-12T20:50:01.978+0000] {subprocess.py:93} INFO -   File "/home/***/.local/lib/python3.12/site-packages/sqlalchemy/pool/base.py", line 327, in connect
[2025-02-12T20:50:01.979+0000] {subprocess.py:93} INFO -     return _ConnectionFairy._checkout(self)
[2025-02-12T20:50:01.979+0000] {subprocess.py:93} INFO -            ^^^^^^^^^^^^^^^^^^^^^^^^^^^^^^^^
[2025-02-12T20:50:01.979+0000] {subprocess.py:93} INFO -   File "/home/***/.local/lib/python3.12/site-packages/sqlalchemy/pool/base.py", line 894, in _checkout
[2025-02-12T20:50:01.980+0000] {subprocess.py:93} INFO -     fairy = _ConnectionRecord.checkout(pool)
[2025-02-12T20:50:01.980+0000] {subprocess.py:93} INFO -             ^^^^^^^^^^^^^^^^^^^^^^^^^^^^^^^^
[2025-02-12T20:50:01.980+0000] {subprocess.py:93} INFO -   File "/home/***/.local/lib/python3.12/site-packages/sqlalchemy/pool/base.py", line 493, in checkout
[2025-02-12T20:50:01.981+0000] {subprocess.py:93} INFO -     rec = pool._do_get()
[2025-02-12T20:50:01.981+0000] {subprocess.py:93} INFO -           ^^^^^^^^^^^^^^
[2025-02-12T20:50:01.981+0000] {subprocess.py:93} INFO -   File "/home/***/.local/lib/python3.12/site-packages/sqlalchemy/pool/impl.py", line 145, in _do_get
[2025-02-12T20:50:01.982+0000] {subprocess.py:93} INFO -     with util.safe_reraise():
[2025-02-12T20:50:01.982+0000] {subprocess.py:93} INFO -   File "/home/***/.local/lib/python3.12/site-packages/sqlalchemy/util/langhelpers.py", line 70, in __exit__
[2025-02-12T20:50:01.982+0000] {subprocess.py:93} INFO -     compat.raise_(
[2025-02-12T20:50:01.982+0000] {subprocess.py:93} INFO -   File "/home/***/.local/lib/python3.12/site-packages/sqlalchemy/util/compat.py", line 211, in raise_
[2025-02-12T20:50:01.983+0000] {subprocess.py:93} INFO -     raise exception
[2025-02-12T20:50:01.983+0000] {subprocess.py:93} INFO -   File "/home/***/.local/lib/python3.12/site-packages/sqlalchemy/pool/impl.py", line 143, in _do_get
[2025-02-12T20:50:01.983+0000] {subprocess.py:93} INFO -     return self._create_connection()
[2025-02-12T20:50:01.983+0000] {subprocess.py:93} INFO -            ^^^^^^^^^^^^^^^^^^^^^^^^^
[2025-02-12T20:50:01.984+0000] {subprocess.py:93} INFO -   File "/home/***/.local/lib/python3.12/site-packages/sqlalchemy/pool/base.py", line 273, in _create_connection
[2025-02-12T20:50:01.984+0000] {subprocess.py:93} INFO -     return _ConnectionRecord(self)
[2025-02-12T20:50:01.984+0000] {subprocess.py:93} INFO -            ^^^^^^^^^^^^^^^^^^^^^^^
[2025-02-12T20:50:01.985+0000] {subprocess.py:93} INFO -   File "/home/***/.local/lib/python3.12/site-packages/sqlalchemy/pool/base.py", line 388, in __init__
[2025-02-12T20:50:01.985+0000] {subprocess.py:93} INFO -     self.__connect()
[2025-02-12T20:50:01.985+0000] {subprocess.py:93} INFO -   File "/home/***/.local/lib/python3.12/site-packages/sqlalchemy/pool/base.py", line 690, in __connect
[2025-02-12T20:50:01.985+0000] {subprocess.py:93} INFO -     with util.safe_reraise():
[2025-02-12T20:50:01.986+0000] {subprocess.py:93} INFO -   File "/home/***/.local/lib/python3.12/site-packages/sqlalchemy/util/langhelpers.py", line 70, in __exit__
[2025-02-12T20:50:01.986+0000] {subprocess.py:93} INFO -     compat.raise_(
[2025-02-12T20:50:01.986+0000] {subprocess.py:93} INFO -   File "/home/***/.local/lib/python3.12/site-packages/sqlalchemy/util/compat.py", line 211, in raise_
[2025-02-12T20:50:01.986+0000] {subprocess.py:93} INFO -     raise exception
[2025-02-12T20:50:01.987+0000] {subprocess.py:93} INFO -   File "/home/***/.local/lib/python3.12/site-packages/sqlalchemy/pool/base.py", line 686, in __connect
[2025-02-12T20:50:01.987+0000] {subprocess.py:93} INFO -     self.dbapi_connection = connection = pool._invoke_creator(self)
[2025-02-12T20:50:01.987+0000] {subprocess.py:93} INFO -                                          ^^^^^^^^^^^^^^^^^^^^^^^^^^
[2025-02-12T20:50:01.987+0000] {subprocess.py:93} INFO -   File "/home/***/.local/lib/python3.12/site-packages/sqlalchemy/engine/create.py", line 574, in connect
[2025-02-12T20:50:01.988+0000] {subprocess.py:93} INFO -     return dialect.connect(*cargs, **cparams)
[2025-02-12T20:50:01.988+0000] {subprocess.py:93} INFO -            ^^^^^^^^^^^^^^^^^^^^^^^^^^^^^^^^^^
[2025-02-12T20:50:01.988+0000] {subprocess.py:93} INFO -   File "/home/***/.local/lib/python3.12/site-packages/sqlalchemy/engine/default.py", line 598, in connect
[2025-02-12T20:50:01.989+0000] {subprocess.py:93} INFO -     return self.dbapi.connect(*cargs, **cparams)
[2025-02-12T20:50:01.989+0000] {subprocess.py:93} INFO -            ^^^^^^^^^^^^^^^^^^^^^^^^^^^^^^^^^^^^^
[2025-02-12T20:50:01.989+0000] {subprocess.py:93} INFO -   File "/home/***/.local/lib/python3.12/site-packages/psycopg2/__init__.py", line 122, in connect
[2025-02-12T20:50:01.990+0000] {subprocess.py:93} INFO -     conn = _connect(dsn, connection_factory=connection_factory, **kwasync)
[2025-02-12T20:50:01.990+0000] {subprocess.py:93} INFO -            ^^^^^^^^^^^^^^^^^^^^^^^^^^^^^^^^^^^^^^^^^^^^^^^^^^^^^^^^^^^^^^^
[2025-02-12T20:50:01.990+0000] {subprocess.py:93} INFO - sqlalchemy.exc.OperationalError: (psycopg2.OperationalError) connection to server at "localhost" (::1), port 5432 failed: Connection refused
[2025-02-12T20:50:01.990+0000] {subprocess.py:93} INFO - 	Is the server running on that host and accepting TCP/IP connections?
[2025-02-12T20:50:01.991+0000] {subprocess.py:93} INFO - connection to server at "localhost" (127.0.0.1), port 5432 failed: Connection refused
[2025-02-12T20:50:01.991+0000] {subprocess.py:93} INFO - 	Is the server running on that host and accepting TCP/IP connections?
[2025-02-12T20:50:01.991+0000] {subprocess.py:93} INFO - 
[2025-02-12T20:50:01.991+0000] {subprocess.py:93} INFO - (Background on this error at: https://sqlalche.me/e/14/e3q8)
[2025-02-12T20:50:02.051+0000] {subprocess.py:97} INFO - Command exited with return code 1
[2025-02-12T20:50:02.052+0000] {taskinstance.py:441} INFO - ::group::Post task execution logs
[2025-02-12T20:50:02.061+0000] {taskinstance.py:2905} ERROR - Task failed with exception
Traceback (most recent call last):
  File "/home/airflow/.local/lib/python3.12/site-packages/airflow/models/taskinstance.py", line 465, in _execute_task
    result = _execute_callable(context=context, **execute_callable_kwargs)
             ^^^^^^^^^^^^^^^^^^^^^^^^^^^^^^^^^^^^^^^^^^^^^^^^^^^^^^^^^^^^^
  File "/home/airflow/.local/lib/python3.12/site-packages/airflow/models/taskinstance.py", line 432, in _execute_callable
    return execute_callable(context=context, **execute_callable_kwargs)
           ^^^^^^^^^^^^^^^^^^^^^^^^^^^^^^^^^^^^^^^^^^^^^^^^^^^^^^^^^^^^
  File "/home/airflow/.local/lib/python3.12/site-packages/airflow/models/baseoperator.py", line 400, in wrapper
    return func(self, *args, **kwargs)
           ^^^^^^^^^^^^^^^^^^^^^^^^^^^
  File "/home/airflow/.local/lib/python3.12/site-packages/airflow/operators/bash.py", line 243, in execute
    raise AirflowException(
airflow.exceptions.AirflowException: Bash command failed. The command returned a non-zero exit code 1.
[2025-02-12T20:50:02.064+0000] {taskinstance.py:1206} INFO - Marking task as UP_FOR_RETRY. dag_id=call_omdb_api, task_id=teste, run_id=scheduled__2025-02-12T20:49:00+00:00, execution_date=20250212T204900, start_date=20250212T205000, end_date=20250212T205002
[2025-02-12T20:50:02.077+0000] {standard_task_runner.py:110} ERROR - Failed to execute job 153 for task teste (Bash command failed. The command returned a non-zero exit code 1.; 867)
[2025-02-12T20:50:02.114+0000] {local_task_job_runner.py:240} INFO - Task exited with return code 1
[2025-02-12T20:50:02.129+0000] {taskinstance.py:3498} INFO - 0 downstream tasks scheduled from follow-on schedule check
[2025-02-12T20:50:02.131+0000] {local_task_job_runner.py:222} INFO - ::endgroup::
