[2025-02-12T21:43:48.101+0000] {local_task_job_runner.py:120} INFO - ::group::Pre task execution logs
[2025-02-12T21:43:48.123+0000] {taskinstance.py:2076} INFO - Dependencies all met for dep_context=non-requeueable deps ti=<TaskInstance: call_omdb_api.teste scheduled__2025-02-12T21:42:00+00:00 [queued]>
[2025-02-12T21:43:48.129+0000] {taskinstance.py:2076} INFO - Dependencies all met for dep_context=requeueable deps ti=<TaskInstance: call_omdb_api.teste scheduled__2025-02-12T21:42:00+00:00 [queued]>
[2025-02-12T21:43:48.130+0000] {taskinstance.py:2306} INFO - Starting attempt 1 of 2
[2025-02-12T21:43:48.143+0000] {taskinstance.py:2330} INFO - Executing <Task(BashOperator): teste> on 2025-02-12 21:42:00+00:00
[2025-02-12T21:43:48.150+0000] {warnings.py:110} WARNING - /home/***/.local/lib/python3.12/site-packages/***/task/task_runner/standard_task_runner.py:61: DeprecationWarning: This process (pid=69) is multi-threaded, use of fork() may lead to deadlocks in the child.
  pid = os.fork()

[2025-02-12T21:43:48.152+0000] {standard_task_runner.py:90} INFO - Running: ['***', 'tasks', 'run', 'call_omdb_api', 'teste', 'scheduled__2025-02-12T21:42:00+00:00', '--job-id', '186', '--raw', '--subdir', 'DAGS_FOLDER/call_api.py', '--cfg-path', '/tmp/tmpmcnmhqqx']
[2025-02-12T21:43:48.153+0000] {standard_task_runner.py:63} INFO - Started process 71 to run task
[2025-02-12T21:43:48.153+0000] {standard_task_runner.py:91} INFO - Job 186: Subtask teste
[2025-02-12T21:43:48.201+0000] {task_command.py:426} INFO - Running <TaskInstance: call_omdb_api.teste scheduled__2025-02-12T21:42:00+00:00 [running]> on host f78167f6e17e
[2025-02-12T21:43:48.303+0000] {taskinstance.py:2648} INFO - Exporting env vars: AIRFLOW_CTX_DAG_OWNER='Celso Cazetto' AIRFLOW_CTX_DAG_ID='call_omdb_api' AIRFLOW_CTX_TASK_ID='teste' AIRFLOW_CTX_EXECUTION_DATE='2025-02-12T21:42:00+00:00' AIRFLOW_CTX_TRY_NUMBER='1' AIRFLOW_CTX_DAG_RUN_ID='scheduled__2025-02-12T21:42:00+00:00'
[2025-02-12T21:43:48.304+0000] {taskinstance.py:430} INFO - ::endgroup::
[2025-02-12T21:43:48.337+0000] {subprocess.py:63} INFO - Tmp dir root location: /tmp
[2025-02-12T21:43:48.338+0000] {subprocess.py:75} INFO - Running command: ['/usr/bin/bash', '-c', 'python /opt/***/pipeline/main.py']
[2025-02-12T21:43:48.355+0000] {subprocess.py:86} INFO - Output:
[2025-02-12T21:43:50.165+0000] {subprocess.py:93} INFO - 2025-02-12 21:43:50,165 - INFO - ESTOU RODANDO ESSA PORRA
[2025-02-12T21:43:50.174+0000] {subprocess.py:93} INFO - 2025-02-12 21:43:50,173 - INFO - Carregando o arquivo de configuração
[2025-02-12T21:43:50.175+0000] {subprocess.py:93} INFO - 2025-02-12 21:43:50,175 - INFO - Buscando os dados de filme do ID:tt0499549
[2025-02-12T21:43:50.601+0000] {subprocess.py:93} INFO - 2025-02-12 21:43:50,600 - INFO - Dados da API carregados com sucesso
[2025-02-12T21:43:50.601+0000] {subprocess.py:93} INFO - 2025-02-12 21:43:50,601 - INFO - Iniciando transformação dos dados.
[2025-02-12T21:43:50.614+0000] {subprocess.py:93} INFO - 2025-02-12 21:43:50,614 - INFO - Estabelecendo conexão com o banco de dados:
[2025-02-12T21:43:50.647+0000] {subprocess.py:93} INFO - 2025-02-12 21:43:50,647 - INFO - Conexão estabelecida com sucesso.
[2025-02-12T21:43:50.671+0000] {subprocess.py:93} INFO - 2025-02-12 21:43:50,671 - INFO - Iniciando o inserção na tabela: omdb.filmes
[2025-02-12T21:43:50.675+0000] {subprocess.py:93} INFO - 2025-02-12 21:43:50,675 - INFO - 0 Inseridos na tabela omdb.filmes
[2025-02-12T21:43:50.679+0000] {subprocess.py:93} INFO - 2025-02-12 21:43:50,678 - INFO - Iniciando o inserção na tabela: omdb.genero
[2025-02-12T21:43:50.682+0000] {subprocess.py:93} INFO - 2025-02-12 21:43:50,682 - INFO - 0 Inseridos na tabela omdb.genero
[2025-02-12T21:43:50.691+0000] {subprocess.py:93} INFO - 2025-02-12 21:43:50,691 - INFO - Iniciando o inserção na tabela: omdb.filme_genero
[2025-02-12T21:43:50.693+0000] {subprocess.py:93} INFO - 2025-02-12 21:43:50,693 - INFO - 0 Inseridos na tabela omdb.filme_genero
[2025-02-12T21:43:50.694+0000] {subprocess.py:93} INFO - 1.4.52
[2025-02-12T21:43:50.695+0000] {subprocess.py:93} INFO - Traceback (most recent call last):
[2025-02-12T21:43:50.695+0000] {subprocess.py:93} INFO -   File "/opt/***/pipeline/main.py", line 90, in <module>
[2025-02-12T21:43:50.696+0000] {subprocess.py:93} INFO -     conn.insere_filmes(filme_df, 'filmes', genero_df, 'genero', 'filme_genero', 'omdb')
[2025-02-12T21:43:50.696+0000] {subprocess.py:93} INFO -   File "/opt/***/pipeline/connection.py", line 79, in insere_filmes
[2025-02-12T21:43:50.698+0000] {subprocess.py:93} INFO -     self.close()
[2025-02-12T21:43:50.698+0000] {subprocess.py:93} INFO -   File "/opt/***/pipeline/connection.py", line 36, in close
[2025-02-12T21:43:50.700+0000] {subprocess.py:93} INFO -     self.conn.commit()
[2025-02-12T21:43:50.700+0000] {subprocess.py:93} INFO -     ^^^^^^^^^^^^^^^^
[2025-02-12T21:43:50.700+0000] {subprocess.py:93} INFO - AttributeError: 'Connection' object has no attribute 'commit'
[2025-02-12T21:43:50.900+0000] {subprocess.py:97} INFO - Command exited with return code 1
[2025-02-12T21:43:50.900+0000] {taskinstance.py:441} INFO - ::group::Post task execution logs
[2025-02-12T21:43:50.911+0000] {taskinstance.py:2905} ERROR - Task failed with exception
Traceback (most recent call last):
  File "/home/airflow/.local/lib/python3.12/site-packages/airflow/models/taskinstance.py", line 465, in _execute_task
    result = _execute_callable(context=context, **execute_callable_kwargs)
             ^^^^^^^^^^^^^^^^^^^^^^^^^^^^^^^^^^^^^^^^^^^^^^^^^^^^^^^^^^^^^
  File "/home/airflow/.local/lib/python3.12/site-packages/airflow/models/taskinstance.py", line 432, in _execute_callable
    return execute_callable(context=context, **execute_callable_kwargs)
           ^^^^^^^^^^^^^^^^^^^^^^^^^^^^^^^^^^^^^^^^^^^^^^^^^^^^^^^^^^^^
  File "/home/airflow/.local/lib/python3.12/site-packages/airflow/models/baseoperator.py", line 400, in wrapper
    return func(self, *args, **kwargs)
           ^^^^^^^^^^^^^^^^^^^^^^^^^^^
  File "/home/airflow/.local/lib/python3.12/site-packages/airflow/operators/bash.py", line 243, in execute
    raise AirflowException(
airflow.exceptions.AirflowException: Bash command failed. The command returned a non-zero exit code 1.
[2025-02-12T21:43:50.914+0000] {taskinstance.py:1206} INFO - Marking task as UP_FOR_RETRY. dag_id=call_omdb_api, task_id=teste, run_id=scheduled__2025-02-12T21:42:00+00:00, execution_date=20250212T214200, start_date=20250212T214348, end_date=20250212T214350
[2025-02-12T21:43:50.926+0000] {standard_task_runner.py:110} ERROR - Failed to execute job 186 for task teste (Bash command failed. The command returned a non-zero exit code 1.; 71)
[2025-02-12T21:43:50.935+0000] {local_task_job_runner.py:240} INFO - Task exited with return code 1
[2025-02-12T21:43:50.954+0000] {taskinstance.py:3498} INFO - 0 downstream tasks scheduled from follow-on schedule check
[2025-02-12T21:43:50.956+0000] {local_task_job_runner.py:222} INFO - ::endgroup::
