[2025-02-12T20:04:01.912+0000] {task_context_logger.py:104} ERROR - Executor reports task instance <TaskInstance: call_omdb_api.teste scheduled__2025-02-12T20:02:00+00:00 [queued]> finished (failed) although the task says it's queued. (Info: None) Was the task killed externally?
