[2025-02-12T22:48:00.631+0000] {local_task_job_runner.py:123} INFO - ::group::Pre task execution logs
[2025-02-12T22:48:00.644+0000] {taskinstance.py:2614} INFO - Dependencies all met for dep_context=non-requeueable deps ti=<TaskInstance: call_omdb_api.teste scheduled__2025-02-12T22:47:00+00:00 [queued]>
[2025-02-12T22:48:00.649+0000] {taskinstance.py:2614} INFO - Dependencies all met for dep_context=requeueable deps ti=<TaskInstance: call_omdb_api.teste scheduled__2025-02-12T22:47:00+00:00 [queued]>
[2025-02-12T22:48:00.650+0000] {taskinstance.py:2867} INFO - Starting attempt 1 of 2
[2025-02-12T22:48:00.660+0000] {taskinstance.py:2890} INFO - Executing <Task(BashOperator): teste> on 2025-02-12 22:47:00+00:00
[2025-02-12T22:48:00.664+0000] {warnings.py:112} WARNING - /home/***/.local/lib/python3.12/site-packages/***/task/task_runner/standard_task_runner.py:70: DeprecationWarning: This process (pid=236) is multi-threaded, use of fork() may lead to deadlocks in the child.
  pid = os.fork()

[2025-02-12T22:48:00.665+0000] {standard_task_runner.py:72} INFO - Started process 237 to run task
[2025-02-12T22:48:00.666+0000] {standard_task_runner.py:104} INFO - Running: ['***', 'tasks', 'run', 'call_omdb_api', 'teste', 'scheduled__2025-02-12T22:47:00+00:00', '--job-id', '8', '--raw', '--subdir', 'DAGS_FOLDER/call_api.py', '--cfg-path', '/tmp/tmpd9sdj2s5']
[2025-02-12T22:48:00.667+0000] {standard_task_runner.py:105} INFO - Job 8: Subtask teste
[2025-02-12T22:48:00.702+0000] {task_command.py:467} INFO - Running <TaskInstance: call_omdb_api.teste scheduled__2025-02-12T22:47:00+00:00 [running]> on host 30c3af0630df
[2025-02-12T22:48:00.758+0000] {taskinstance.py:3134} INFO - Exporting env vars: AIRFLOW_CTX_DAG_OWNER='Celso Cazetto' AIRFLOW_CTX_DAG_ID='call_omdb_api' AIRFLOW_CTX_TASK_ID='teste' AIRFLOW_CTX_EXECUTION_DATE='2025-02-12T22:47:00+00:00' AIRFLOW_CTX_TRY_NUMBER='1' AIRFLOW_CTX_DAG_RUN_ID='scheduled__2025-02-12T22:47:00+00:00'
[2025-02-12T22:48:00.759+0000] {taskinstance.py:732} INFO - ::endgroup::
[2025-02-12T22:48:00.769+0000] {subprocess.py:78} INFO - Tmp dir root location: /tmp
[2025-02-12T22:48:00.769+0000] {subprocess.py:88} INFO - Running command: ['/usr/bin/bash', '-c', 'python /opt/***/pipeline/main.py']
[2025-02-12T22:48:00.777+0000] {subprocess.py:99} INFO - Output:
[2025-02-12T22:48:01.701+0000] {subprocess.py:106} INFO - 2025-02-12 22:48:01,701 - INFO - ESTOU RODANDO ESSA PORRA
[2025-02-12T22:48:01.702+0000] {subprocess.py:106} INFO - 2025-02-12 22:48:01,702 - INFO - Carregando o arquivo de configuração
[2025-02-12T22:48:01.703+0000] {subprocess.py:106} INFO - 2025-02-12 22:48:01,703 - INFO - Buscando os dados de filme do ID:tt0499549
[2025-02-12T22:48:01.809+0000] {subprocess.py:106} INFO - 2025-02-12 22:48:01,809 - INFO - Dados da API carregados com sucesso
[2025-02-12T22:48:01.810+0000] {subprocess.py:106} INFO - 2025-02-12 22:48:01,809 - INFO - Iniciando transformação dos dados.
[2025-02-12T22:48:01.817+0000] {subprocess.py:106} INFO - 2025-02-12 22:48:01,817 - INFO - Estabelecendo conexão com o banco de dados:
[2025-02-12T22:48:01.846+0000] {subprocess.py:106} INFO - 2025-02-12 22:48:01,846 - INFO - Conexão estabelecida com sucesso.
[2025-02-12T22:48:01.864+0000] {subprocess.py:106} INFO - 2025-02-12 22:48:01,864 - INFO - Iniciando o inserção na tabela: omdb.filmes
[2025-02-12T22:48:01.868+0000] {subprocess.py:106} INFO - 2025-02-12 22:48:01,868 - INFO - 0 Inseridos na tabela omdb.filmes
[2025-02-12T22:48:01.871+0000] {subprocess.py:106} INFO - 2025-02-12 22:48:01,871 - INFO - Iniciando o inserção na tabela: omdb.genero
[2025-02-12T22:48:01.874+0000] {subprocess.py:106} INFO - 2025-02-12 22:48:01,874 - INFO - 0 Inseridos na tabela omdb.genero
[2025-02-12T22:48:01.882+0000] {subprocess.py:106} INFO - 2025-02-12 22:48:01,882 - INFO - Iniciando o inserção na tabela: omdb.filme_genero
[2025-02-12T22:48:01.884+0000] {subprocess.py:106} INFO - 2025-02-12 22:48:01,884 - INFO - 0 Inseridos na tabela omdb.filme_genero
[2025-02-12T22:48:01.885+0000] {subprocess.py:106} INFO - 1.4.54
[2025-02-12T22:48:01.885+0000] {subprocess.py:106} INFO - Traceback (most recent call last):
[2025-02-12T22:48:01.886+0000] {subprocess.py:106} INFO -   File "/opt/***/pipeline/main.py", line 90, in <module>
[2025-02-12T22:48:01.887+0000] {subprocess.py:106} INFO -     conn.insere_filmes(filme_df, 'filmes', genero_df, 'genero', 'filme_genero', 'omdb')
[2025-02-12T22:48:01.887+0000] {subprocess.py:106} INFO -   File "/opt/***/pipeline/connection.py", line 79, in insere_filmes
[2025-02-12T22:48:01.889+0000] {subprocess.py:106} INFO -     self.close()
[2025-02-12T22:48:01.889+0000] {subprocess.py:106} INFO -   File "/opt/***/pipeline/connection.py", line 36, in close
[2025-02-12T22:48:01.890+0000] {subprocess.py:106} INFO -     self.conn.commit()
[2025-02-12T22:48:01.891+0000] {subprocess.py:106} INFO -     ^^^^^^^^^^^^^^^^
[2025-02-12T22:48:01.891+0000] {subprocess.py:106} INFO - AttributeError: 'Connection' object has no attribute 'commit'
[2025-02-12T22:48:01.971+0000] {subprocess.py:110} INFO - Command exited with return code 1
[2025-02-12T22:48:01.981+0000] {taskinstance.py:3313} ERROR - Task failed with exception
Traceback (most recent call last):
  File "/home/airflow/.local/lib/python3.12/site-packages/airflow/models/taskinstance.py", line 768, in _execute_task
    result = _execute_callable(context=context, **execute_callable_kwargs)
             ^^^^^^^^^^^^^^^^^^^^^^^^^^^^^^^^^^^^^^^^^^^^^^^^^^^^^^^^^^^^^
  File "/home/airflow/.local/lib/python3.12/site-packages/airflow/models/taskinstance.py", line 734, in _execute_callable
    return ExecutionCallableRunner(
           ^^^^^^^^^^^^^^^^^^^^^^^^
  File "/home/airflow/.local/lib/python3.12/site-packages/airflow/utils/operator_helpers.py", line 252, in run
    return self.func(*args, **kwargs)
           ^^^^^^^^^^^^^^^^^^^^^^^^^^
  File "/home/airflow/.local/lib/python3.12/site-packages/airflow/models/baseoperator.py", line 424, in wrapper
    return func(self, *args, **kwargs)
           ^^^^^^^^^^^^^^^^^^^^^^^^^^^
  File "/home/airflow/.local/lib/python3.12/site-packages/airflow/operators/bash.py", line 276, in execute
    raise AirflowException(
airflow.exceptions.AirflowException: Bash command failed. The command returned a non-zero exit code 1.
[2025-02-12T22:48:01.987+0000] {taskinstance.py:1226} INFO - Marking task as UP_FOR_RETRY. dag_id=call_omdb_api, task_id=teste, run_id=scheduled__2025-02-12T22:47:00+00:00, execution_date=20250212T224700, start_date=20250212T224800, end_date=20250212T224801
[2025-02-12T22:48:02.009+0000] {taskinstance.py:341} INFO - ::group::Post task execution logs
[2025-02-12T22:48:02.010+0000] {standard_task_runner.py:124} ERROR - Failed to execute job 8 for task teste (Bash command failed. The command returned a non-zero exit code 1.; 237)
Traceback (most recent call last):
  File "/home/airflow/.local/lib/python3.12/site-packages/airflow/task/task_runner/standard_task_runner.py", line 117, in _start_by_fork
    ret = args.func(args, dag=self.dag)
          ^^^^^^^^^^^^^^^^^^^^^^^^^^^^^
  File "/home/airflow/.local/lib/python3.12/site-packages/airflow/cli/cli_config.py", line 49, in command
    return func(*args, **kwargs)
           ^^^^^^^^^^^^^^^^^^^^^
  File "/home/airflow/.local/lib/python3.12/site-packages/airflow/utils/cli.py", line 116, in wrapper
    return f(*args, **kwargs)
           ^^^^^^^^^^^^^^^^^^
  File "/home/airflow/.local/lib/python3.12/site-packages/airflow/cli/commands/task_command.py", line 483, in task_run
    task_return_code = _run_task_by_selected_method(args, _dag, ti)
                       ^^^^^^^^^^^^^^^^^^^^^^^^^^^^^^^^^^^^^^^^^^^^
  File "/home/airflow/.local/lib/python3.12/site-packages/airflow/cli/commands/task_command.py", line 256, in _run_task_by_selected_method
    return _run_raw_task(args, ti)
           ^^^^^^^^^^^^^^^^^^^^^^^
  File "/home/airflow/.local/lib/python3.12/site-packages/airflow/cli/commands/task_command.py", line 341, in _run_raw_task
    return ti._run_raw_task(
           ^^^^^^^^^^^^^^^^^
  File "/home/airflow/.local/lib/python3.12/site-packages/airflow/utils/session.py", line 97, in wrapper
    return func(*args, session=session, **kwargs)
           ^^^^^^^^^^^^^^^^^^^^^^^^^^^^^^^^^^^^^^
  File "/home/airflow/.local/lib/python3.12/site-packages/airflow/models/taskinstance.py", line 3006, in _run_raw_task
    return _run_raw_task(
           ^^^^^^^^^^^^^^
  File "/home/airflow/.local/lib/python3.12/site-packages/airflow/models/taskinstance.py", line 274, in _run_raw_task
    TaskInstance._execute_task_with_callbacks(
  File "/home/airflow/.local/lib/python3.12/site-packages/airflow/models/taskinstance.py", line 3161, in _execute_task_with_callbacks
    result = self._execute_task(context, task_orig)
             ^^^^^^^^^^^^^^^^^^^^^^^^^^^^^^^^^^^^^^
  File "/home/airflow/.local/lib/python3.12/site-packages/airflow/models/taskinstance.py", line 3185, in _execute_task
    return _execute_task(self, context, task_orig)
           ^^^^^^^^^^^^^^^^^^^^^^^^^^^^^^^^^^^^^^^
  File "/home/airflow/.local/lib/python3.12/site-packages/airflow/models/taskinstance.py", line 768, in _execute_task
    result = _execute_callable(context=context, **execute_callable_kwargs)
             ^^^^^^^^^^^^^^^^^^^^^^^^^^^^^^^^^^^^^^^^^^^^^^^^^^^^^^^^^^^^^
  File "/home/airflow/.local/lib/python3.12/site-packages/airflow/models/taskinstance.py", line 734, in _execute_callable
    return ExecutionCallableRunner(
           ^^^^^^^^^^^^^^^^^^^^^^^^
  File "/home/airflow/.local/lib/python3.12/site-packages/airflow/utils/operator_helpers.py", line 252, in run
    return self.func(*args, **kwargs)
           ^^^^^^^^^^^^^^^^^^^^^^^^^^
  File "/home/airflow/.local/lib/python3.12/site-packages/airflow/models/baseoperator.py", line 424, in wrapper
    return func(self, *args, **kwargs)
           ^^^^^^^^^^^^^^^^^^^^^^^^^^^
  File "/home/airflow/.local/lib/python3.12/site-packages/airflow/operators/bash.py", line 276, in execute
    raise AirflowException(
airflow.exceptions.AirflowException: Bash command failed. The command returned a non-zero exit code 1.
[2025-02-12T22:48:02.043+0000] {local_task_job_runner.py:266} INFO - Task exited with return code 1
[2025-02-12T22:48:02.060+0000] {taskinstance.py:3901} INFO - 0 downstream tasks scheduled from follow-on schedule check
[2025-02-12T22:48:02.061+0000] {local_task_job_runner.py:245} INFO - ::endgroup::
