[2025-02-12T19:58:01.862+0000] {local_task_job_runner.py:120} INFO - ::group::Pre task execution logs
[2025-02-12T19:58:01.882+0000] {taskinstance.py:2076} INFO - Dependencies all met for dep_context=non-requeueable deps ti=<TaskInstance: call_omdb_api.teste scheduled__2025-02-12T19:56:00+00:00 [queued]>
[2025-02-12T19:58:01.888+0000] {taskinstance.py:2076} INFO - Dependencies all met for dep_context=requeueable deps ti=<TaskInstance: call_omdb_api.teste scheduled__2025-02-12T19:56:00+00:00 [queued]>
[2025-02-12T19:58:01.889+0000] {taskinstance.py:2306} INFO - Starting attempt 2 of 2
[2025-02-12T19:58:01.900+0000] {taskinstance.py:2330} INFO - Executing <Task(PythonOperator): teste> on 2025-02-12 19:56:00+00:00
[2025-02-12T19:58:01.905+0000] {warnings.py:110} WARNING - /home/***/.local/lib/python3.12/site-packages/***/task/task_runner/standard_task_runner.py:61: DeprecationWarning: This process (pid=670) is multi-threaded, use of fork() may lead to deadlocks in the child.
  pid = os.fork()

[2025-02-12T19:58:01.906+0000] {standard_task_runner.py:63} INFO - Started process 671 to run task
[2025-02-12T19:58:01.906+0000] {standard_task_runner.py:90} INFO - Running: ['***', 'tasks', 'run', 'call_omdb_api', 'teste', 'scheduled__2025-02-12T19:56:00+00:00', '--job-id', '65', '--raw', '--subdir', 'DAGS_FOLDER/call_api.py', '--cfg-path', '/tmp/tmper8u6re9']
[2025-02-12T19:58:01.907+0000] {standard_task_runner.py:91} INFO - Job 65: Subtask teste
[2025-02-12T19:58:01.943+0000] {task_command.py:426} INFO - Running <TaskInstance: call_omdb_api.teste scheduled__2025-02-12T19:56:00+00:00 [running]> on host f82bf6a6274c
[2025-02-12T19:58:02.020+0000] {taskinstance.py:2648} INFO - Exporting env vars: AIRFLOW_CTX_DAG_OWNER='Celso Cazetto' AIRFLOW_CTX_DAG_ID='call_omdb_api' AIRFLOW_CTX_TASK_ID='teste' AIRFLOW_CTX_EXECUTION_DATE='2025-02-12T19:56:00+00:00' AIRFLOW_CTX_TRY_NUMBER='2' AIRFLOW_CTX_DAG_RUN_ID='scheduled__2025-02-12T19:56:00+00:00'
[2025-02-12T19:58:02.021+0000] {taskinstance.py:430} INFO - ::endgroup::
[2025-02-12T19:58:02.031+0000] {logging_mixin.py:188} INFO - CURRENT PATH /opt/***
[2025-02-12T19:58:02.031+0000] {taskinstance.py:441} INFO - ::group::Post task execution logs
[2025-02-12T19:58:02.032+0000] {taskinstance.py:2905} ERROR - Task failed with exception
Traceback (most recent call last):
  File "/home/airflow/.local/lib/python3.12/site-packages/airflow/models/taskinstance.py", line 465, in _execute_task
    result = _execute_callable(context=context, **execute_callable_kwargs)
             ^^^^^^^^^^^^^^^^^^^^^^^^^^^^^^^^^^^^^^^^^^^^^^^^^^^^^^^^^^^^^
  File "/home/airflow/.local/lib/python3.12/site-packages/airflow/models/taskinstance.py", line 432, in _execute_callable
    return execute_callable(context=context, **execute_callable_kwargs)
           ^^^^^^^^^^^^^^^^^^^^^^^^^^^^^^^^^^^^^^^^^^^^^^^^^^^^^^^^^^^^
  File "/home/airflow/.local/lib/python3.12/site-packages/airflow/models/baseoperator.py", line 400, in wrapper
    return func(self, *args, **kwargs)
           ^^^^^^^^^^^^^^^^^^^^^^^^^^^
  File "/home/airflow/.local/lib/python3.12/site-packages/airflow/operators/python.py", line 235, in execute
    return_value = self.execute_callable()
                   ^^^^^^^^^^^^^^^^^^^^^^^
  File "/home/airflow/.local/lib/python3.12/site-packages/airflow/operators/python.py", line 252, in execute_callable
    return self.python_callable(*self.op_args, **self.op_kwargs)
           ^^^^^^^^^^^^^^^^^^^^^^^^^^^^^^^^^^^^^^^^^^^^^^^^^^^^^
  File "/opt/airflow/dags/call_api.py", line 23, in call_api
    path_test = os.path.exists(os.getcwd(), 'pipeline')
                ^^^^^^^^^^^^^^^^^^^^^^^^^^^^^^^^^^^^^^^
TypeError: exists() takes 1 positional argument but 2 were given
[2025-02-12T19:58:02.042+0000] {taskinstance.py:1206} INFO - Marking task as FAILED. dag_id=call_omdb_api, task_id=teste, run_id=scheduled__2025-02-12T19:56:00+00:00, execution_date=20250212T195600, start_date=20250212T195801, end_date=20250212T195802
[2025-02-12T19:58:02.053+0000] {standard_task_runner.py:110} ERROR - Failed to execute job 65 for task teste (exists() takes 1 positional argument but 2 were given; 671)
[2025-02-12T19:58:02.080+0000] {local_task_job_runner.py:240} INFO - Task exited with return code 1
[2025-02-12T19:58:02.094+0000] {taskinstance.py:3498} INFO - 0 downstream tasks scheduled from follow-on schedule check
[2025-02-12T19:58:02.096+0000] {local_task_job_runner.py:222} INFO - ::endgroup::
